Workbook

Sheet 月数据汇总
A2: 1月 | B2: Cost 花费 | C2: IMP 展示 | D2: Click 点击 | E2: Order 订单 | F2: Sales 销量 | G2: ShoppingCart 加入购物车 | H2: Bookmark-Product 宝贝收藏 | I2: Bookmark-Store 店铺收藏 | J2: CTR 点击率 | K2: CPC 点击成本 | L2: CPM 千次展现成本 | M2: ROI 投资回报率 | N2: CVR 点击转化率 | O2: ASP 订单均价 | P2: Cporder 订单成本 | Q2: CPshopping cart 加购成本
A3: 钻展 | B3: 6.05 | C3: 1427 | D3: 1 | E3: - | F3: - | G3: - | H3: - | I3: - | J3: - | K3: - | L3: - | M3: - | N3: - | O3: - | P3: - | Q3: -
A4: 明星店铺 | B4: 2731.45 | C4: 7691 | D4: 349 | E4: 0 | F4: 0 | G4: 2 | H4: 2 | I4: 11 | J4: =D4/C4 -> 0.045377714 | K4: =B4/D4 -> 7.8265043 | L4: =(B4/C4)*1000 -> 355.14888 | M4: =F4/B4 -> 0 | N4: =E4/D4 -> 0 | O4: =F4/E4 -> #DIV/0! | P4: =B4/E4 -> #DIV/0! | Q4: =B4/G4 -> 1365.725
A5: 直通车 | B5: 1952.96 | C5: 39544 | D5: 1253 | E5: 2 | F5: 198 | G5: 46 | H5: 4 | I5: 8 | J5: =D5/C5 -> 0.031686223 | K5: =B5/D5 -> 1.5586273 | L5: =(B5/C5)*1000 -> 49.387012 | M5: =F5/B5 -> 0.10138456 | N5: =E5/D5 -> 0.0015961692 | O5: =F5/E5 -> 99 | P5: =B5/E5 -> 976.48 | Q5: =B5/G5 -> 42.455652
A6: 引力魔方 | B6: - | C6: - | D6: - | E6: - | F6: - | G6: - | H6: - | I6: - | J6: - | K6: - | L6: - | M6: - | N6: - | O6: - | P6: - | Q6: -
A7: 总计 | B7: =SUM(B3:B6) -> 4690.46 | C7: =SUM(C3:C6) -> 48662 | D7: =SUM(D3:D6) -> 1603 | E7: =SUM(E3:E6) -> 2 | F7: =SUM(F3:F6) -> 198 | G7: =SUM(G3:G6) -> 48 | H7: =SUM(H3:H6) -> 6 | I7: =SUM(I3:I6) -> 19 | J7: =D7/C7 -> 0.032941515 | K7: =B7/D7 -> 2.9260512 | L7: =(B7/C7)*1000 -> 96.388558 | M7: =F7/B7 -> 0.042213344 | N7: =E7/D7 -> 0.0012476606 | O7: =F7/E7 -> 99 | P7: =B7/E7 -> 2345.23 | Q7: =B7/G7 -> 97.717917
A10: 2月 | B10: Cost 花费 | C10: IMP 展示 | D10: Click 点击 | E10: Order 订单 | F10: Sales 销量 | G10: ShoppingCart 加入购物车 | H10: Bookmark-Product 宝贝收藏 | I10: Bookmark-Store 店铺收藏 | J10: CTR 点击率 | K10: CPC 点击成本 | L10: CPM 千次展现成本 | M10: ROI 投资回报率 | N10: CVR 点击转化率 | O10: ASP 订单均价 | P10: Cporder 订单成本 | Q10: CPshopping cart 加购成本
A11: 明星店铺 | B11: 22646 | C11: 24719 | D11: 1047 | E11: 1 | F11: 99 | G11: 13 | H11: 3 | I11: 20 | J11: =D11/C11 -> 0.042356082 | K11: =B11/D11 -> 21.629417 | L11: =(B11/C11)*1000 -> 916.13738 | M11: =F11/B11 -> 0.004371633 | N11: =E11/D11 -> 0.00095510984 | O11: =F11/E11 -> 99 | P11: =B11/E11 -> 22646 | Q11: =B11/G11 -> 1742
A12: 直通车 | B12: 5688.53 | C12: 84202 | D12: 2773 | E12: 2 | F12: 198 | G12: 51 | H12: 14 | I12: 14 | J12: =D12/C12 -> 0.032932709 | K12: =B12/D12 -> 2.0513992 | L12: =(B12/C12)*1000 -> 67.558134 | M12: =F12/B12 -> 0.034806883 | N12: =E12/D12 -> 0.00072124053 | O12: =F12/E12 -> 99 | P12: =B12/E12 -> 2844.265 | Q12: =B12/G12 -> 111.5398
A13: 引力魔方 | B13: 1337.93 | C13: 197627 | D13: 1649 | E13: 0 | F13: 0 | G13: 8 | H13: 12 | I13: 2 | J13: =D13/C13 -> 0.0083440016 | K13: =B13/D13 -> 0.8113584 | L13: =(B13/C13)*1000 -> 6.7699758 | M13: =F13/B13 -> 0 | N13: =E13/D13 -> 0 | O13: =F13/E13 -> #DIV/0! | P13: =B13/E13 -> #DIV/0! | Q13: =B13/G13 -> 167.24125
A14: 总计 | B14: =SUM(B11:B13) -> 29672.46 | C14: =SUM(C11:C13) -> 306548 | D14: =SUM(D11:D13) -> 5469 | E14: =SUM(E11:E13) -> 3 | F14: =SUM(F11:F13) -> 297 | G14: =SUM(G11:G13) -> 72 | H14: =SUM(H11:H13) -> 29 | I14: =SUM(I11:I13) -> 36 | J14: =D14/C14 -> 0.017840599 | K14: =B14/D14 -> 5.4255732 | L14: =(B14/C14)*1000 -> 96.795477 | M14: =F14/B14 -> 0.010009281 | N14: =E14/D14 -> 0.00054854635 | O14: =F14/E14 -> 99 | P14: =B14/E14 -> 9890.82 | Q14: =B14/G14 -> 412.1175
A17: 3月 | B17: Cost 花费 | C17: IMP 展示 | D17: Click 点击 | E17: Order 订单 | F17: Sales 销量 | G17: ShoppingCart 加入购物车 | H17: Bookmark-Product 宝贝收藏 | I17: Bookmark-Store 店铺收藏 | J17: CTR 点击率 | K17: CPC 点击成本 | L17: CPM 千次展现成本 | M17: ROI 投资回报率 | N17: CVR 点击转化率 | O17: ASP 订单均价 | P17: Cporder 订单成本 | Q17: CPshopping cart 加购成本
A18: 明星店铺 | B18: 2866.29 | C18: 12670 | D18: 404 | E18: 3 | F18: 600 | G18: 2 | H18: 1 | I18: 12 | J18: =D18/C18 -> 0.031886346 | K18: =B18/D18 -> 7.0947772 | L18: =(B18/C18)*1000 -> 226.22652 | M18: =F18/B18 -> 0.20932983 | N18: =E18/D18 -> 0.0074257426 | O18: =F18/E18 -> 200 | P18: =B18/E18 -> 955.43 | Q18: =B18/G18 -> 1433.145
A19: 直通车 | B19: 3311.5 | C19: 120004 | D19: 2346 | E19: 0 | F19: 0 | G19: 1 | H19: 2 | I19: 8 | J19: =D19/C19 -> 0.019549348 | K19: =B19/D19 -> 1.4115516 | L19: =(B19/C19)*1000 -> 27.594914 | M19: =F19/B19 -> 0 | N19: =E19/D19 -> 0 | O19: =F19/E19 -> #DIV/0! | P19: =B19/E19 -> #DIV/0! | Q19: =B19/G19 -> 3311.5
A20: 引力魔方 | B20: 2031.5 | C20: 219571 | D20: 1511 | E20: 0 | F20: 0 | G20: 2 | H20: 14 | I20: 0 | J20: =D20/C20 -> 0.0068816009 | K20: =B20/D20 -> 1.3444739 | L20: =(B20/C20)*1000 -> 9.2521326 | M20: =F20/B20 -> 0 | N20: =E20/D20 -> 0 | O20: =F20/E20 -> #DIV/0! | P20: =B20/E20 -> #DIV/0! | Q20: =B20/G20 -> 1015.75
A21: 总计 | B21: =SUM(B18:B20) -> 8209.29 | C21: =SUM(C18:C20) -> 352245 | D21: =SUM(D18:D20) -> 4261 | E21: =SUM(E18:E20) -> 3 | F21: =SUM(F18:F20) -> 600 | G21: =SUM(G18:G20) -> 5 | H21: =SUM(H18:H20) -> 17 | I21: =SUM(I18:I20) -> 20 | J21: =D21/C21 -> 0.012096694 | K21: =B21/D21 -> 1.9266111 | L21: =(B21/C21)*1000 -> 23.305625 | M21: =F21/B21 -> 0.073087928 | N21: =E21/D21 -> 0.00070406008 | O21: =F21/E21 -> 200 | P21: =B21/E21 -> 2736.43 | Q21: =B21/G21 -> 1641.858
A25: 2023年
A26: 8月 | B26: Cost 花费 | C26: IMP 展示 | D26: Click 点击 | E26: Order 订单 | F26: Sales 销量 | G26: ShoppingCart 加入购物车 | H26: Bookmark-Product 宝贝收藏 | I26: Bookmark-Store 店铺收藏 | J26: CTR 点击率 | K26: CPC 点击成本 | L26: CPM 千次展现成本 | M26: ROI 投资回报率 | N26: CVR 点击转化率 | O26: ASP 订单均价 | P26: Cporder 订单成本 | Q26: CPshopping cart 加购成本
A27: 明星店铺 | B27: =SUM(明星店铺!B514:B522) -> 496.42 | C27: =SUM(明星店铺!C514:C522) -> 670 | D27: =SUM(明星店铺!D514:D522) -> 180 | E27: =SUM(明星店铺!E514:E522) -> 3 | F27: =SUM(明星店铺!F514:F522) -> 3 | G27: =SUM(明星店铺!G514:G522) -> 38 | H27: =SUM(明星店铺!H514:H522) -> 8 | I27: =SUM(明星店铺!I514:I522) -> 6 | J27: =D27/C27 -> 0.26865672 | K27: =B27/D27 -> 2.7578889 | L27: =(B27/C27)*1000 -> 740.92537 | M27: =F27/B27 -> 0.0060432698 | N27: =E27/D27 -> 0.016666667 | O27: =F27/E27 -> 1 | P27: =B27/E27 -> 165.47333 | Q27: =B27/G27 -> 13.063684
A28: 直通车 | B28: =SUM(直通车!B514:B522) -> 8646.78 | C28: =SUM(直通车!C514:C522) -> 32943 | D28: =SUM(直通车!D514:D522) -> 2523 | E28: =SUM(直通车!E514:E522) -> 1 | F28: =SUM(直通车!F514:F522) -> 1 | G28: =SUM(直通车!G514:G522) -> 62 | H28: =SUM(直通车!H514:H522) -> 37 | I28: =SUM(直通车!I514:I522) -> 12 | J28: =D28/C28 -> 0.076586832 | K28: =B28/D28 -> 3.4271819 | L28: =(B28/C28)*1000 -> 262.47701 | M28: =F28/B28 -> 0.00011564999 | N28: =E28/D28 -> 0.00039635355 | O28: =F28/E28 -> 1 | P28: =B28/E28 -> 8646.78 | Q28: =B28/G28 -> 139.46419
A29: 引力魔方 | B29: =SUM(引力魔方!B413:B421) -> 4176.9 | C29: =SUM(引力魔方!C413:C421) -> 444197 | D29: =SUM(引力魔方!D413:D421) -> 2732 | E29: =SUM(引力魔方!E413:E421) -> 0 | F29: =SUM(引力魔方!F413:F421) -> 0 | G29: =SUM(引力魔方!G413:G421) -> 25 | H29: =SUM(引力魔方!H413:H421) -> 14 | I29: =SUM(引力魔方!I413:I421) -> 2 | J29: =D29/C29 -> 0.0061504242 | K29: =B29/D29 -> 1.5288799 | L29: =(B29/C29)*1000 -> 9.4032603 | M29: =F29/B29 -> 0 | N29: =E29/D29 -> 0 | O29: =F29/E29 -> #DIV/0! | P29: =B29/E29 -> #DIV/0! | Q29: =B29/G29 -> 167.076
A30: 万相台 | B30: =SUM(万相台!B2:B10) -> 1014.03 | C30: =SUM(万相台!C2:C10) -> 96394 | D30: =SUM(万相台!D2:D10) -> 1126 | E30: =SUM(万相台!E2:E10) -> 0 | F30: =SUM(万相台!F2:F10) -> 0 | G30: =SUM(万相台!G2:G10) -> 22 | H30: =SUM(万相台!H2:H10) -> 12 | J30: =D30/C30 -> 0.011681225 | K30: =B30/D30 -> 0.9005595 | L30: =(B30/C30)*1000 -> 10.519638 | M30: =F30/B30 -> 0 | N30: =E30/D30 -> 0 | O30: =F30/E30 -> #DIV/0! | P30: =B30/E30 -> #DIV/0! | Q30: =B30/G30 -> 46.092273
A31: 总计 | B31: =SUM(B27:B30) -> 14334.13 | C31: =SUM(C27:C30) -> 574204 | D31: =SUM(D27:D30) -> 6561 | E31: =SUM(E27:E30) -> 4 | F31: =SUM(F27:F30) -> 4 | G31: =SUM(G27:G30) -> 147 | H31: =SUM(H27:H30) -> 71 | I31: =SUM(I27:I30) -> 20 | J31: =D31/C31 -> 0.011426253 | K31: =B31/D31 -> 2.1847478 | L31: =(B31/C31)*1000 -> 24.96348 | M31: =F31/B31 -> 0.00027905426 | N31: =E31/D31 -> 0.00060966316 | O31: =F31/E31 -> 1 | P31: =B31/E31 -> 3583.5325 | Q31: =B31/G31 -> 97.511088
A33: 9月 | B33: Cost 花费 | C33: IMP 展示 | D33: Click 点击 | E33: Order 订单 | F33: Sales 销量 | G33: ShoppingCart 加入购物车 | H33: Bookmark-Product 宝贝收藏 | I33: Bookmark-Store 店铺收藏 | J33: CTR 点击率 | K33: CPC 点击成本 | L33: CPM 千次展现成本 | M33: ROI 投资回报率 | N33: CVR 点击转化率 | O33: ASP 订单均价 | P33: Cporder 订单成本 | Q33: CPshopping cart 加购成本
A34: 明星店铺 | B34: =SUM(明星店铺!B523:B552) -> 1129.72 | C34: =SUM(明星店铺!C523:C552) -> 1507 | D34: =SUM(明星店铺!D523:D552) -> 586 | E34: =SUM(明星店铺!E523:E552) -> 5 | F34: =SUM(明星店铺!F523:F552) -> 7282.8 | G34: =SUM(明星店铺!G523:G552) -> 84 | H34: =SUM(明星店铺!H523:H552) -> 17 | I34: =SUM(明星店铺!I523:I552) -> 26 | J34: =D34/C34 -> 0.38885202 | K34: =B34/D34 -> 1.9278498 | L34: =(B34/C34)*1000 -> 749.64831 | M34: =F34/B34 -> 6.4465531 | N34: =E34/D34 -> 0.0085324232 | O34: =F34/E34 -> 1456.56 | P34: =B34/E34 -> 225.944 | Q34: =B34/G34 -> 13.449048
A35: 直通车 | B35: =SUM(直通车!B523:B552) -> 38763.28 | C35: =SUM(直通车!C523:C552) -> 174099 | D35: =SUM(直通车!D523:D552) -> 10706 | E35: =SUM(直通车!E523:E552) -> 19 | F35: =SUM(直通车!F523:F552) -> 24965.1 | G35: =SUM(直通车!G523:G552) -> 252 | H35: =SUM(直通车!H523:H552) -> 177 | I35: =SUM(直通车!I523:I552) -> 88 | J35: =D35/C35 -> 0.061493748 | K35: =B35/D35 -> 3.6207061 | L35: =(B35/C35)*1000 -> 222.65079 | M35: =F35/B35 -> 0.64403993 | N35: =E35/D35 -> 0.0017747058 | O35: =F35/E35 -> 1313.9526 | P35: =B35/E35 -> 2040.1726 | Q35: =B35/G35 -> 153.82254
A36: 引力魔方 | B36: =SUM(引力魔方!B422:B451) -> 21321.69 | C36: =SUM(引力魔方!C422:C451) -> 1533981 | D36: =SUM(引力魔方!D422:D451) -> 11155 | E36: =SUM(引力魔方!E422:E451) -> 0 | F36: =SUM(引力魔方!F422:F451) -> 0 | G36: =SUM(引力魔方!G422:G451) -> 103 | H36: =SUM(引力魔方!H422:H451) -> 64 | I36: =SUM(引力魔方!I422:I451) -> 16 | J36: =D36/C36 -> 0.0072719284 | K36: =B36/D36 -> 1.9114021 | L36: =(B36/C36)*1000 -> 13.899579 | M36: =F36/B36 -> 0 | N36: =E36/D36 -> 0 | O36: =F36/E36 -> #DIV/0! | P36: =B36/E36 -> #DIV/0! | Q36: =B36/G36 -> 207.0067
A37: 万相台 | B37: =SUM(万相台!B11:B40) -> 6066.03 | C37: =SUM(万相台!C11:C40) -> 756412 | D37: =SUM(万相台!D11:D40) -> 9008 | E37: =SUM(万相台!E11:E40) -> 7 | F37: =SUM(万相台!F11:F40) -> 6379.9 | G37: =SUM(万相台!G11:G40) -> 115 | H37: =SUM(万相台!H11:H40) -> 96 | J37: =D37/C37 -> 0.011908854 | K37: =B37/D37 -> 0.67340475 | L37: =(B37/C37)*1000 -> 8.0194788 | M37: =F37/B37 -> 1.0517422 | N37: =E37/D37 -> 0.00077708703 | O37: =F37/E37 -> 911.41429 | P37: =B37/E37 -> 866.57571 | Q37: =B37/G37 -> 52.748087
A38: 总计 | B38: =SUM(B34:B37) -> 67280.72 | C38: =SUM(C34:C37) -> 2465999 | D38: =SUM(D34:D37) -> 31455 | E38: =SUM(E34:E37) -> 31 | F38: =SUM(F34:F37) -> 38627.8 | G38: =SUM(G34:G37) -> 554 | H38: =SUM(H34:H37) -> 354 | I38: =SUM(I34:I37) -> 130 | J38: =D38/C38 -> 0.01275548 | K38: =B38/D38 -> 2.1389515 | L38: =(B38/C38)*1000 -> 27.283353 | M38: =F38/B38 -> 0.57412881 | N38: =E38/D38 -> 0.00098553489 | O38: =F38/E38 -> 1246.0581 | P38: =B38/E38 -> 2170.3458 | Q38: =B38/G38 -> 121.44534
A40: 10月 | B40: Cost 花费 | C40: IMP 展示 | D40: Click 点击 | E40: Order 订单 | F40: Sales 销量 | G40: ShoppingCart 加入购物车 | H40: Bookmark-Product 宝贝收藏 | I40: Bookmark-Store 店铺收藏 | J40: CTR 点击率 | K40: CPC 点击成本 | L40: CPM 千次展现成本 | M40: ROI 投资回报率 | N40: CVR 点击转化率 | O40: ASP 订单均价 | P40: Cporder 订单成本 | Q40: CPshopping cart 加购成本
A41: 明星店铺 | B41: =SUM(明星店铺!B553:B583) -> 8005.24 | C41: =SUM(明星店铺!C553:C583) -> 9248 | D41: =SUM(明星店铺!D553:D583) -> 3856 | E41: =SUM(明星店铺!E553:E583) -> 129 | F41: =SUM(明星店铺!F553:F583) -> 1401487.2 | G41: =SUM(明星店铺!G553:G583) -> 747 | H41: =SUM(明星店铺!H553:H583) -> 232 | I41: =SUM(明星店铺!I553:I583) -> 442 | J41: =D41/C41 -> 0.41695502 | K41: =B41/D41 -> 2.0760477 | L41: =(B41/C41)*1000 -> 865.61851 | M41: =F41/B41 -> 175.07123 | N41: =E41/D41 -> 0.033454357 | O41: =F41/E41 -> 10864.242 | P41: =B41/E41 -> 62.056124 | Q41: =B41/G41 -> 10.716519
A42: 直通车 | B42: =SUM(直通车!B553:B583) -> 57558.86 | C42: =SUM(直通车!C553:C583) -> 219210 | D42: =SUM(直通车!D553:D583) -> 18951 | E42: =SUM(直通车!E553:E583) -> 133 | F42: =SUM(直通车!F553:F583) -> 1640797.3 | G42: =SUM(直通车!G553:G583) -> 924 | H42: =SUM(直通车!H553:H583) -> 626 | I42: =SUM(直通车!I553:I583) -> 336 | J42: =D42/C42 -> 0.086451348 | K42: =B42/D42 -> 3.0372466 | L42: =(B42/C42)*1000 -> 262.57406 | M42: =F42/B42 -> 28.506425 | N42: =E42/D42 -> 0.0070180993 | O42: =F42/E42 -> 12336.822 | P42: =B42/E42 -> 432.77338 | Q42: =B42/G42 -> 62.293139
A43: 引力魔方 | B43: =SUM(引力魔方!B452:B482) -> 30457.64 | C43: =SUM(引力魔方!C452:C482) -> 806896 | D43: =SUM(引力魔方!D452:D482) -> 10898 | E43: =SUM(引力魔方!E452:E482) -> 64 | F43: =SUM(引力魔方!F452:F482) -> 665174.8 | G43: =SUM(引力魔方!G452:G482) -> 206 | H43: =SUM(引力魔方!H452:H482) -> 94 | I43: =SUM(引力魔方!I452:I482) -> 78 | J43: =D43/C43 -> 0.013506078 | K43: =B43/D43 -> 2.7947917 | L43: =(B43/C43)*1000 -> 37.746674 | M43: =F43/B43 -> 21.839341 | N43: =E43/D43 -> 0.0058726372 | O43: =F43/E43 -> 10393.356 | P43: =B43/E43 -> 475.90062 | Q43: =B43/G43 -> 147.85262
A44: 万相台 | B44: =SUM(万相台!B41:B71) -> 9480.74 | C44: =SUM(万相台!C41:C71) -> 91699 | D44: =SUM(万相台!D41:D71) -> 4467 | E44: =SUM(万相台!E41:E71) -> 12 | F44: =SUM(万相台!F41:F71) -> 67545.5 | G44: =SUM(万相台!G41:G71) -> 114 | H44: =SUM(万相台!H41:H71) -> 60 | J44: =D44/C44 -> 0.048713726 | K44: =B44/D44 -> 2.1223953 | L44: =(B44/C44)*1000 -> 103.38979 | M44: =F44/B44 -> 7.1244966 | N44: =E44/D44 -> 0.0026863667 | O44: =F44/E44 -> 5628.7917 | P44: =B44/E44 -> 790.06167 | Q44: =B44/G44 -> 83.164386
A45: 总计 | B45: =SUM(B41:B44) -> 105502.48 | C45: =SUM(C41:C44) -> 1127053 | D45: =SUM(D41:D44) -> 38172 | E45: =SUM(E41:E44) -> 338 | F45: =SUM(F41:F44) -> 3775004.8 | G45: =SUM(G41:G44) -> 1991 | H45: =SUM(H41:H44) -> 1012 | I45: =SUM(I41:I44) -> 856 | J45: =D45/C45 -> 0.03386886 | K45: =B45/D45 -> 2.7638709 | L45: =(B45/C45)*1000 -> 93.609156 | M45: =F45/B45 -> 35.781195 | N45: =E45/D45 -> 0.0088546579 | O45: =F45/E45 -> 11168.653 | P45: =B45/E45 -> 312.13751 | Q45: =B45/G45 -> 52.989694
A47: 11月 | B47: Cost 花费 | C47: IMP 展示 | D47: Click 点击 | E47: Order 订单 | F47: Sales 销量 | G47: ShoppingCart 加入购物车 | H47: Bookmark-Product 宝贝收藏 | I47: Bookmark-Store 店铺收藏 | J47: CTR 点击率 | K47: CPC 点击成本 | L47: CPM 千次展现成本 | M47: ROI 投资回报率 | N47: CVR 点击转化率 | O47: ASP 订单均价 | P47: Cporder 订单成本 | Q47: CPshopping cart 加购成本
A48: 明星店铺 | B48: =SUM(明星店铺!B584:B613) -> 6386.06 | C48: =SUM(明星店铺!C584:C613) -> 6596 | D48: =SUM(明星店铺!D584:D613) -> 2650 | E48: =SUM(明星店铺!E584:E613) -> 63 | F48: =SUM(明星店铺!F584:F613) -> 477277.22 | G48: =SUM(明星店铺!G584:G613) -> 661 | H48: =SUM(明星店铺!H584:H613) -> 121 | I48: =SUM(明星店铺!I584:I613) -> 280 | J48: =D48/C48 -> 0.40175864 | K48: =B48/D48 -> 2.409834 | L48: =(B48/C48)*1000 -> 968.17162 | M48: =F48/B48 -> 74.737353 | N48: =E48/D48 -> 0.023773585 | O48: =F48/E48 -> 7575.8289 | P48: =B48/E48 -> 101.36603 | Q48: =B48/G48 -> 9.6612103
A49: 直通车 | B49: =SUM(直通车!B584:B613) -> 85001.26 | C49: =SUM(直通车!C584:C613) -> 273932 | D49: =SUM(直通车!D584:D613) -> 22062 | E49: =SUM(直通车!E584:E613) -> 111 | F49: =SUM(直通车!F584:F613) -> 872404.39 | G49: =SUM(直通车!G584:G613) -> 1099 | H49: =SUM(直通车!H584:H613) -> 513 | I49: =SUM(直通车!I584:I613) -> 285 | J49: =D49/C49 -> 0.080538236 | K49: =B49/D49 -> 3.8528356 | L49: =(B49/C49)*1000 -> 310.30059 | M49: =F49/B49 -> 10.263429 | N49: =E49/D49 -> 0.0050312755 | O49: =F49/E49 -> 7859.499 | P49: =B49/E49 -> 765.77712 | Q49: =B49/G49 -> 77.344186
A50: 引力魔方 | B50: =SUM(引力魔方!B483:B512) -> 47468.12 | C50: =SUM(引力魔方!C483:C512) -> 3705258 | D50: =SUM(引力魔方!D483:D512) -> 43076 | E50: =SUM(引力魔方!E483:E512) -> 48 | F50: =SUM(引力魔方!F483:F512) -> 489457.12 | G50: =SUM(引力魔方!G483:G512) -> 606 | H50: =SUM(引力魔方!H483:H512) -> 175 | I50: =SUM(引力魔方!I483:I512) -> 79 | J50: =D50/C50 -> 0.011625641 | K50: =B50/D50 -> 1.1019621 | L50: =(B50/C50)*1000 -> 12.811016 | M50: =F50/B50 -> 10.311281 | N50: =E50/D50 -> 0.0011143096 | O50: =F50/E50 -> 10197.023 | P50: =B50/E50 -> 988.91917 | Q50: =B50/G50 -> 78.330231
A51: 万相台 | B51: =SUM(万相台!B72:B101) -> 10182.62 | C51: =SUM(万相台!C72:C101) -> 257113 | D51: =SUM(万相台!D72:D101) -> 10905 | E51: =SUM(万相台!E72:E101) -> 29 | F51: =SUM(万相台!F72:F101) -> 265570.08 | G51: =SUM(万相台!G72:G101) -> 231 | H51: =SUM(万相台!H72:H101) -> 56 | J51: =D51/C51 -> 0.042413258 | K51: =B51/D51 -> 0.93375699 | L51: =(B51/C51)*1000 -> 39.603676 | M51: =F51/B51 -> 26.080722 | N51: =E51/D51 -> 0.0026593306 | O51: =F51/E51 -> 9157.589 | P51: =B51/E51 -> 351.12483 | Q51: =B51/G51 -> 44.080606
...

Sheet 月数据汇总-
A2: 1月 | B2: Cost 花费 | C2: IMP 展示 | D2: Click 点击 | E2: Order 订单 | F2: Sales 销量 | G2: ShoppingCart 加入购物车 | H2: Bookmark-Product 宝贝收藏 | I2: Bookmark-Store 店铺收藏 | K2: CTR 点击率 | L2: CPC 点击成本 | M2: CPM 千次展现成本 | N2: ROI 投资回报率 | O2: CVR 点击转化率 | P2: ASP 订单均价 | Q2: Cporder 订单成本 | R2: CPshopping cart 加购成本
A3: 钻展 | B3: 6.05 | C3: 1427 | D3: 1 | E3: - | F3: - | G3: - | H3: - | I3: - | K3: - | L3: - | M3: - | N3: - | O3: - | P3: - | Q3: - | R3: -
A4: 明星店铺 | B4: 2731.45 | C4: 7691 | D4: 349 | E4: 0 | F4: 0 | G4: 2 | H4: 2 | I4: 11 | K4: =D4/C4 -> 0.045377714 | L4: =B4/D4 -> 7.8265043 | M4: =(B4/C4)*1000 -> 355.14888 | N4: =F4/B4 -> 0 | O4: =E4/D4 -> 0 | P4: =F4/E4 -> #DIV/0! | Q4: =B4/E4 -> #DIV/0! | R4: =B4/G4 -> 1365.725
A5: 直通车 | B5: 1952.96 | C5: 39544 | D5: 1253 | E5: 2 | F5: 198 | G5: 46 | H5: 4 | I5: 8 | K5: =D5/C5 -> 0.031686223 | L5: =B5/D5 -> 1.5586273 | M5: =(B5/C5)*1000 -> 49.387012 | N5: =F5/B5 -> 0.10138456 | O5: =E5/D5 -> 0.0015961692 | P5: =F5/E5 -> 99 | Q5: =B5/E5 -> 976.48 | R5: =B5/G5 -> 42.455652
A6: 引力魔方 | B6: - | C6: - | D6: - | E6: - | F6: - | G6: - | H6: - | I6: - | K6: - | L6: - | M6: - | N6: - | O6: - | P6: - | Q6: - | R6: -
A7: 总计 | B7: =SUM(B3:B6) -> 4690.46 | C7: =SUM(C3:C6) -> 48662 | D7: =SUM(D3:D6) -> 1603 | E7: =SUM(E3:E6) -> 2 | F7: =SUM(F3:F6) -> 198 | G7: =SUM(G3:G6) -> 48 | H7: =SUM(H3:H6) -> 6 | I7: =SUM(I3:I6) -> 19 | K7: =D7/C7 -> 0.032941515 | L7: =B7/D7 -> 2.9260512 | M7: =(B7/C7)*1000 -> 96.388558 | N7: =F7/B7 -> 0.042213344 | O7: =E7/D7 -> 0.0012476606 | P7: =F7/E7 -> 99 | Q7: =B7/E7 -> 2345.23 | R7: =B7/G7 -> 97.717917
A10: 2月 | B10: Cost 花费 | C10: IMP 展示 | D10: Click 点击 | E10: Order 订单 | F10: Sales 销量 | G10: ShoppingCart 加入购物车 | H10: Bookmark-Product 宝贝收藏 | I10: Bookmark-Store 店铺收藏 | K10: CTR 点击率 | L10: CPC 点击成本 | M10: CPM 千次展现成本 | N10: ROI 投资回报率 | O10: CVR 点击转化率 | P10: ASP 订单均价 | Q10: Cporder 订单成本 | R10: CPshopping cart 加购成本
A11: 明星店铺 | B11: 22646 | C11: 24719 | D11: 1047 | E11: 1 | F11: 99 | G11: 13 | H11: 3 | I11: 20 | K11: =D11/C11 -> 0.042356082 | L11: =B11/D11 -> 21.629417 | M11: =(B11/C11)*1000 -> 916.13738 | N11: =F11/B11 -> 0.004371633 | O11: =E11/D11 -> 0.00095510984 | P11: =F11/E11 -> 99 | Q11: =B11/E11 -> 22646 | R11: =B11/G11 -> 1742
A12: 直通车 | B12: 5688.53 | C12: 84202 | D12: 2773 | E12: 2 | F12: 198 | G12: 51 | H12: 14 | I12: 14 | K12: =D12/C12 -> 0.032932709 | L12: =B12/D12 -> 2.0513992 | M12: =(B12/C12)*1000 -> 67.558134 | N12: =F12/B12 -> 0.034806883 | O12: =E12/D12 -> 0.00072124053 | P12: =F12/E12 -> 99 | Q12: =B12/E12 -> 2844.265 | R12: =B12/G12 -> 111.5398
A13: 引力魔方 | B13: 1337.93 | C13: 197627 | D13: 1649 | E13: 0 | F13: 0 | G13: 8 | H13: 12 | I13: 2 | K13: =D13/C13 -> 0.0083440016 | L13: =B13/D13 -> 0.8113584 | M13: =(B13/C13)*1000 -> 6.7699758 | N13: =F13/B13 -> 0 | O13: =E13/D13 -> 0 | P13: =F13/E13 -> #DIV/0! | Q13: =B13/E13 -> #DIV/0! | R13: =B13/G13 -> 167.24125
A14: 总计 | B14: =SUM(B11:B13) -> 29672.46 | C14: =SUM(C11:C13) -> 306548 | D14: =SUM(D11:D13) -> 5469 | E14: =SUM(E11:E13) -> 3 | F14: =SUM(F11:F13) -> 297 | G14: =SUM(G11:G13) -> 72 | H14: =SUM(H11:H13) -> 29 | I14: =SUM(I11:I13) -> 36 | K14: =D14/C14 -> 0.017840599 | L14: =B14/D14 -> 5.4255732 | M14: =(B14/C14)*1000 -> 96.795477 | N14: =F14/B14 -> 0.010009281 | O14: =E14/D14 -> 0.00054854635 | P14: =F14/E14 -> 99 | Q14: =B14/E14 -> 9890.82 | R14: =B14/G14 -> 412.1175
A17: 3月 | B17: Cost 花费 | C17: IMP 展示 | D17: Click 点击 | E17: Order 订单 | F17: Sales 销量 | G17: ShoppingCart 加入购物车 | H17: Bookmark-Product 宝贝收藏 | I17: Bookmark-Store 店铺收藏 | K17: CTR 点击率 | L17: CPC 点击成本 | M17: CPM 千次展现成本 | N17: ROI 投资回报率 | O17: CVR 点击转化率 | P17: ASP 订单均价 | Q17: Cporder 订单成本 | R17: CPshopping cart 加购成本
A18: 明星店铺 | B18: 2866.29 | C18: 12670 | D18: 404 | E18: 3 | F18: 600 | G18: 2 | H18: 1 | I18: 12 | K18: =D18/C18 -> 0.031886346 | L18: =B18/D18 -> 7.0947772 | M18: =(B18/C18)*1000 -> 226.22652 | N18: =F18/B18 -> 0.20932983 | O18: =E18/D18 -> 0.0074257426 | P18: =F18/E18 -> 200 | Q18: =B18/E18 -> 955.43 | R18: =B18/G18 -> 1433.145
A19: 直通车 | B19: 3311.5 | C19: 120004 | D19: 2346 | E19: 0 | F19: 0 | G19: 1 | H19: 2 | I19: 8 | K19: =D19/C19 -> 0.019549348 | L19: =B19/D19 -> 1.4115516 | M19: =(B19/C19)*1000 -> 27.594914 | N19: =F19/B19 -> 0 | O19: =E19/D19 -> 0 | P19: =F19/E19 -> #DIV/0! | Q19: =B19/E19 -> #DIV/0! | R19: =B19/G19 -> 3311.5
A20: 引力魔方 | B20: 2031.5 | C20: 219571 | D20: 1511 | E20: 0 | F20: 0 | G20: 2 | H20: 14 | I20: 0 | K20: =D20/C20 -> 0.0068816009 | L20: =B20/D20 -> 1.3444739 | M20: =(B20/C20)*1000 -> 9.2521326 | N20: =F20/B20 -> 0 | O20: =E20/D20 -> 0 | P20: =F20/E20 -> #DIV/0! | Q20: =B20/E20 -> #DIV/0! | R20: =B20/G20 -> 1015.75
A21: 总计 | B21: =SUM(B18:B20) -> 8209.29 | C21: =SUM(C18:C20) -> 352245 | D21: =SUM(D18:D20) -> 4261 | E21: =SUM(E18:E20) -> 3 | F21: =SUM(F18:F20) -> 600 | G21: =SUM(G18:G20) -> 5 | H21: =SUM(H18:H20) -> 17 | I21: =SUM(I18:I20) -> 20 | K21: =D21/C21 -> 0.012096694 | L21: =B21/D21 -> 1.9266111 | M21: =(B21/C21)*1000 -> 23.305625 | N21: =F21/B21 -> 0.073087928 | O21: =E21/D21 -> 0.00070406008 | P21: =F21/E21 -> 200 | Q21: =B21/E21 -> 2736.43 | R21: =B21/G21 -> 1641.858
A25: 2023年
A26: 8月 | B26: Cost 花费 | C26: IMP 展示 | D26: Click 点击 | E26: Order 订单 | F26: Sales 销量 | G26: ShoppingCart 加入购物车 | H26: Bookmark-Product 宝贝收藏 | I26: Bookmark-Store 店铺收藏 | K26: CTR 点击率 | L26: CPC 点击成本 | M26: CPM 千次展现成本 | N26: ROI 投资回报率 | O26: CVR 点击转化率 | P26: ASP 订单均价 | Q26: Cporder 订单成本 | R26: CPshopping cart 加购成本
A27: 明星店铺 | B27: =SUM(明星店铺!B514:B522) -> 496.42 | C27: =SUM(明星店铺!C514:C522) -> 670 | D27: =SUM(明星店铺!D514:D522) -> 180 | E27: =SUM(明星店铺!E514:E522) -> 3 | F27: =SUM(明星店铺!F514:F522) -> 3 | G27: =SUM(明星店铺!G514:G522) -> 38 | H27: =SUM(明星店铺!H514:H522) -> 8 | I27: =SUM(明星店铺!I514:I522) -> 6 | K27: =D27/C27 -> 0.26865672 | L27: =B27/D27 -> 2.7578889 | M27: =(B27/C27)*1000 -> 740.92537 | N27: =F27/B27 -> 0.0060432698 | O27: =E27/D27 -> 0.016666667 | P27: =F27/E27 -> 1 | Q27: =B27/E27 -> 165.47333 | R27: =B27/G27 -> 13.063684
A28: 直通车 | B28: =SUM(直通车!B514:B522) -> 8646.78 | C28: =SUM(直通车!C514:C522) -> 32943 | D28: =SUM(直通车!D514:D522) -> 2523 | E28: =SUM(直通车!E514:E522) -> 1 | F28: =SUM(直通车!F514:F522) -> 1 | G28: =SUM(直通车!G514:G522) -> 62 | H28: =SUM(直通车!H514:H522) -> 37 | I28: =SUM(直通车!I514:I522) -> 12 | K28: =D28/C28 -> 0.076586832 | L28: =B28/D28 -> 3.4271819 | M28: =(B28/C28)*1000 -> 262.47701 | N28: =F28/B28 -> 0.00011564999 | O28: =E28/D28 -> 0.00039635355 | P28: =F28/E28 -> 1 | Q28: =B28/E28 -> 8646.78 | R28: =B28/G28 -> 139.46419
A29: 引力魔方 | B29: =SUM(引力魔方!B413:B421) -> 4176.9 | C29: =SUM(引力魔方!C413:C421) -> 444197 | D29: =SUM(引力魔方!D413:D421) -> 2732 | E29: =SUM(引力魔方!E413:E421) -> 0 | F29: =SUM(引力魔方!F413:F421) -> 0 | G29: =SUM(引力魔方!G413:G421) -> 25 | H29: =SUM(引力魔方!H413:H421) -> 14 | I29: =SUM(引力魔方!I413:I421) -> 2 | K29: =D29/C29 -> 0.0061504242 | L29: =B29/D29 -> 1.5288799 | M29: =(B29/C29)*1000 -> 9.4032603 | N29: =F29/B29 -> 0 | O29: =E29/D29 -> 0 | P29: =F29/E29 -> #DIV/0! | Q29: =B29/E29 -> #DIV/0! | R29: =B29/G29 -> 167.076
A30: 万相台 | B30: =SUM(万相台!B2:B10) -> 1014.03 | C30: =SUM(万相台!C2:C10) -> 96394 | D30: =SUM(万相台!D2:D10) -> 1126 | E30: =SUM(万相台!E2:E10) -> 0 | F30: =SUM(万相台!F2:F10) -> 0 | G30: =SUM(万相台!G2:G10) -> 22 | H30: =SUM(万相台!H2:H10) -> 12 | K30: =D30/C30 -> 0.011681225 | L30: =B30/D30 -> 0.9005595 | M30: =(B30/C30)*1000 -> 10.519638 | N30: =F30/B30 -> 0 | O30: =E30/D30 -> 0 | P30: =F30/E30 -> #DIV/0! | Q30: =B30/E30 -> #DIV/0! | R30: =B30/G30 -> 46.092273
A31: 总计 | B31: =SUM(B27:B30) -> 14334.13 | C31: =SUM(C27:C30) -> 574204 | D31: =SUM(D27:D30) -> 6561 | E31: =SUM(E27:E30) -> 4 | F31: =SUM(F27:F30) -> 4 | G31: =SUM(G27:G30) -> 147 | H31: =SUM(H27:H30) -> 71 | I31: =SUM(I27:I30) -> 20 | K31: =D31/C31 -> 0.011426253 | L31: =B31/D31 -> 2.1847478 | M31: =(B31/C31)*1000 -> 24.96348 | N31: =F31/B31 -> 0.00027905426 | O31: =E31/D31 -> 0.00060966316 | P31: =F31/E31 -> 1 | Q31: =B31/E31 -> 3583.5325 | R31: =B31/G31 -> 97.511088
A33: 9月 | B33: Cost 花费 | C33: IMP 展示 | D33: Click 点击 | E33: Order 订单 | F33: Sales 销量 | G33: ShoppingCart 加入购物车 | H33: Bookmark-Product 宝贝收藏 | I33: Bookmark-Store 店铺收藏 | J33: 总收藏数 | K33: CTR 点击率 | L33: CPC 点击成本 | M33: CPM 千次展现成本 | N33: ROI 投资回报率 | O33: CVR 点击转化率 | P33: ASP 订单均价 | Q33: Cporder 订单成本 | R33: CPshopping cart 加购成本
A34: 明星店铺 | B34: =SUM(明星店铺!B523:B552) -> 1129.72 | C34: =SUM(明星店铺!C523:C552) -> 1507 | D34: =SUM(明星店铺!D523:D552) -> 586 | E34: =SUM(明星店铺!E523:E552) -> 5 | F34: =SUM(明星店铺!F523:F552) -> 7282.8 | G34: =SUM(明星店铺!G523:G552) -> 84 | H34: =SUM(明星店铺!H523:H552) -> 17 | I34: =SUM(明星店铺!I523:I552) -> 26 | J34: =H34+I34 -> 43 | K34: =D34/C34 -> 0.38885202 | L34: =B34/D34 -> 1.9278498 | M34: =(B34/C34)*1000 -> 749.64831 | N34: =F34/B34 -> 6.4465531 | O34: =E34/D34 -> 0.0085324232 | P34: =F34/E34 -> 1456.56 | Q34: =B34/E34 -> 225.944 | R34: =B34/G34 -> 13.449048
A35: 直通车 | B35: =SUM(直通车!B523:B552) -> 38763.28 | C35: =SUM(直通车!C523:C552) -> 174099 | D35: =SUM(直通车!D523:D552) -> 10706 | E35: =SUM(直通车!E523:E552) -> 19 | F35: =SUM(直通车!F523:F552) -> 24965.1 | G35: =SUM(直通车!G523:G552) -> 252 | H35: =SUM(直通车!H523:H552) -> 177 | I35: =SUM(直通车!I523:I552) -> 88 | J35: =H35+I35 -> 265 | K35: =D35/C35 -> 0.061493748 | L35: =B35/D35 -> 3.6207061 | M35: =(B35/C35)*1000 -> 222.65079 | N35: =F35/B35 -> 0.64403993 | O35: =E35/D35 -> 0.0017747058 | P35: =F35/E35 -> 1313.9526 | Q35: =B35/E35 -> 2040.1726 | R35: =B35/G35 -> 153.82254
A36: 引力魔方 | B36: =SUM(引力魔方!B422:B451) -> 21321.69 | C36: =SUM(引力魔方!C422:C451) -> 1533981 | D36: =SUM(引力魔方!D422:D451) -> 11155 | E36: =SUM(引力魔方!E422:E451) -> 0 | F36: =SUM(引力魔方!F422:F451) -> 0 | G36: =SUM(引力魔方!G422:G451) -> 103 | H36: =SUM(引力魔方!H422:H451) -> 64 | I36: =SUM(引力魔方!I422:I451) -> 16 | J36: =H36+I36 -> 80 | K36: =D36/C36 -> 0.0072719284 | L36: =B36/D36 -> 1.9114021 | M36: =(B36/C36)*1000 -> 13.899579 | N36: =F36/B36 -> 0 | O36: =E36/D36 -> 0 | P36: =F36/E36 -> #DIV/0! | Q36: =B36/E36 -> #DIV/0! | R36: =B36/G36 -> 207.0067
A37: 万相台 | B37: =SUM(万相台!B11:B40) -> 6066.03 | C37: =SUM(万相台!C11:C40) -> 756412 | D37: =SUM(万相台!D11:D40) -> 9008 | E37: =SUM(万相台!E11:E40) -> 7 | F37: =SUM(万相台!F11:F40) -> 6379.9 | G37: =SUM(万相台!G11:G40) -> 115 | H37: =SUM(万相台!H11:H40) -> 96 | J37: =H37+I37 -> 96 | K37: =D37/C37 -> 0.011908854 | L37: =B37/D37 -> 0.67340475 | M37: =(B37/C37)*1000 -> 8.0194788 | N37: =F37/B37 -> 1.0517422 | O37: =E37/D37 -> 0.00077708703 | P37: =F37/E37 -> 911.41429 | Q37: =B37/E37 -> 866.57571 | R37: =B37/G37 -> 52.748087
A38: 总计 | B38: =SUM(B34:B37) -> 67280.72 | C38: =SUM(C34:C37) -> 2465999 | D38: =SUM(D34:D37) -> 31455 | E38: =SUM(E34:E37) -> 31 | F38: =SUM(F34:F37) -> 38627.8 | G38: =SUM(G34:G37) -> 554 | H38: =SUM(H34:H37) -> 354 | I38: =SUM(I34:I37) -> 130 | J38: =H38+I38 -> 484 | K38: =D38/C38 -> 0.01275548 | L38: =B38/D38 -> 2.1389515 | M38: =(B38/C38)*1000 -> 27.283353 | N38: =F38/B38 -> 0.57412881 | O38: =E38/D38 -> 0.00098553489 | P38: =F38/E38 -> 1246.0581 | Q38: =B38/E38 -> 2170.3458 | R38: =B38/G38 -> 121.44534
A40: 10月 | B40: Cost 花费 | C40: IMP 展示 | D40: Click 点击 | E40: Order 订单 | F40: Sales 销量 | G40: ShoppingCart 加入购物车 | H40: Bookmark-Product 宝贝收藏 | I40: Bookmark-Store 店铺收藏 | J40: 总收藏数 | K40: CTR 点击率 | L40: CPC 点击成本 | M40: CPM 千次展现成本 | N40: ROI 投资回报率 | O40: CVR 点击转化率 | P40: ASP 订单均价 | Q40: Cporder 订单成本 | R40: CPshopping cart 加购成本
A41: 明星店铺 | B41: =SUM(明星店铺!B553:B583) -> 8005.24 | C41: =SUM(明星店铺!C553:C583) -> 9248 | D41: =SUM(明星店铺!D553:D583) -> 3856 | E41: =SUM(明星店铺!E553:E583) -> 129 | F41: =SUM(明星店铺!F553:F583) -> 1401487.2 | G41: =SUM(明星店铺!G553:G583) -> 747 | H41: =SUM(明星店铺!H553:H583) -> 232 | I41: =SUM(明星店铺!I553:I583) -> 442 | J41: =H41+I41 -> 674 | K41: =D41/C41 -> 0.41695502 | L41: =B41/D41 -> 2.0760477 | M41: =(B41/C41)*1000 -> 865.61851 | N41: =F41/B41 -> 175.07123 | O41: =E41/D41 -> 0.033454357 | P41: =F41/E41 -> 10864.242 | Q41: =B41/E41 -> 62.056124 | R41: =B41/G41 -> 10.716519
A42: 直通车 | B42: =SUM(直通车!B553:B583) -> 57558.86 | C42: =SUM(直通车!C553:C583) -> 219210 | D42: =SUM(直通车!D553:D583) -> 18951 | E42: =SUM(直通车!E553:E583) -> 133 | F42: =SUM(直通车!F553:F583) -> 1640797.3 | G42: =SUM(直通车!G553:G583) -> 924 | H42: =SUM(直通车!H553:H583) -> 626 | I42: =SUM(直通车!I553:I583) -> 336 | J42: =H42+I42 -> 962 | K42: =D42/C42 -> 0.086451348 | L42: =B42/D42 -> 3.0372466 | M42: =(B42/C42)*1000 -> 262.57406 | N42: =F42/B42 -> 28.506425 | O42: =E42/D42 -> 0.0070180993 | P42: =F42/E42 -> 12336.822 | Q42: =B42/E42 -> 432.77338 | R42: =B42/G42 -> 62.293139
A43: 引力魔方 | B43: =SUM(引力魔方!B452:B482) -> 30457.64 | C43: =SUM(引力魔方!C452:C482) -> 806896 | D43: =SUM(引力魔方!D452:D482) -> 10898 | E43: =SUM(引力魔方!E452:E482) -> 64 | F43: =SUM(引力魔方!F452:F482) -> 665174.8 | G43: =SUM(引力魔方!G452:G482) -> 206 | H43: =SUM(引力魔方!H452:H482) -> 94 | I43: =SUM(引力魔方!I452:I482) -> 78 | J43: =H43+I43 -> 172 | K43: =D43/C43 -> 0.013506078 | L43: =B43/D43 -> 2.7947917 | M43: =(B43/C43)*1000 -> 37.746674 | N43: =F43/B43 -> 21.839341 | O43: =E43/D43 -> 0.0058726372 | P43: =F43/E43 -> 10393.356 | Q43: =B43/E43 -> 475.90062 | R43: =B43/G43 -> 147.85262
A44: 万相台 | B44: =SUM(万相台!B41:B71) -> 9480.74 | C44: =SUM(万相台!C41:C71) -> 91699 | D44: =SUM(万相台!D41:D71) -> 4467 | E44: =SUM(万相台!E41:E71) -> 12 | F44: =SUM(万相台!F41:F71) -> 67545.5 | G44: =SUM(万相台!G41:G71) -> 114 | H44: =SUM(万相台!H41:H71) -> 60 | J44: =H44+I44 -> 60 | K44: =D44/C44 -> 0.048713726 | L44: =B44/D44 -> 2.1223953 | M44: =(B44/C44)*1000 -> 103.38979 | N44: =F44/B44 -> 7.1244966 | O44: =E44/D44 -> 0.0026863667 | P44: =F44/E44 -> 5628.7917 | Q44: =B44/E44 -> 790.06167 | R44: =B44/G44 -> 83.164386
A45: 总计 | B45: =SUM(B41:B44) -> 105502.48 | C45: =SUM(C41:C44) -> 1127053 | D45: =SUM(D41:D44) -> 38172 | E45: =SUM(E41:E44) -> 338 | F45: =SUM(F41:F44) -> 3775004.8 | G45: =SUM(G41:G44) -> 1991 | H45: =SUM(H41:H44) -> 1012 | I45: =SUM(I41:I44) -> 856 | J45: =H45+I45 -> 1868 | K45: =D45/C45 -> 0.03386886 | L45: =B45/D45 -> 2.7638709 | M45: =(B45/C45)*1000 -> 93.609156 | N45: =F45/B45 -> 35.781195 | O45: =E45/D45 -> 0.0088546579 | P45: =F45/E45 -> 11168.653 | Q45: =B45/E45 -> 312.13751 | R45: =B45/G45 -> 52.989694
A47: 11月 | B47: Cost 花费 | C47: IMP 展示 | D47: Click 点击 | E47: Order 订单 | F47: Sales 销量 | G47: ShoppingCart 加入购物车 | H47: Bookmark-Product 宝贝收藏 | I47: Bookmark-Store 店铺收藏 | J47: 总收藏数 | K47: CTR 点击率 | L47: CPC 点击成本 | M47: CPM 千次展现成本 | N47: ROI 投资回报率 | O47: CVR 点击转化率 | P47: ASP 订单均价 | Q47: Cporder 订单成本 | R47: CPshopping cart 加购成本
A48: 明星店铺 | B48: =SUM(明星店铺!B584:B613) -> 6386.06 | C48: =SUM(明星店铺!C584:C613) -> 6596 | D48: =SUM(明星店铺!D584:D613) -> 2650 | E48: =SUM(明星店铺!E584:E613) -> 63 | F48: =SUM(明星店铺!F584:F613) -> 477277.22 | G48: =SUM(明星店铺!G584:G613) -> 661 | H48: =SUM(明星店铺!H584:H613) -> 121 | I48: =SUM(明星店铺!I584:I613) -> 280 | J48: =H48+I48 -> 401 | K48: =D48/C48 -> 0.40175864 | L48: =B48/D48 -> 2.409834 | M48: =(B48/C48)*1000 -> 968.17162 | N48: =F48/B48 -> 74.737353 | O48: =E48/D48 -> 0.023773585 | P48: =F48/E48 -> 7575.8289 | Q48: =B48/E48 -> 101.36603 | R48: =B48/G48 -> 9.6612103
A49: 直通车 | B49: =SUM(直通车!B584:B613) -> 85001.26 | C49: =SUM(直通车!C584:C613) -> 273932 | D49: =SUM(直通车!D584:D613) -> 22062 | E49: =SUM(直通车!E584:E613) -> 111 | F49: =SUM(直通车!F584:F613) -> 872404.39 | G49: =SUM(直通车!G584:G613) -> 1099 | H49: =SUM(直通车!H584:H613) -> 513 | I49: =SUM(直通车!I584:I613) -> 285 | J49: =H49+I49 -> 798 | K49: =D49/C49 -> 0.080538236 | L49: =B49/D49 -> 3.8528356 | M49: =(B49/C49)*1000 -> 310.30059 | N49: =F49/B49 -> 10.263429 | O49: =E49/D49 -> 0.0050312755 | P49: =F49/E49 -> 7859.499 | Q49: =B49/E49 -> 765.77712 | R49: =B49/G49 -> 77.344186
A50: 引力魔方 | B50: =SUM(引力魔方!B483:B512) -> 47468.12 | C50: =SUM(引力魔方!C483:C512) -> 3705258 | D50: =SUM(引力魔方!D483:D512) -> 43076 | E50: =SUM(引力魔方!E483:E512) -> 48 | F50: =SUM(引力魔方!F483:F512) -> 489457.12 | G50: =SUM(引力魔方!G483:G512) -> 606 | H50: =SUM(引力魔方!H483:H512) -> 175 | I50: =SUM(引力魔方!I483:I512) -> 79 | J50: =H50+I50 -> 254 | K50: =D50/C50 -> 0.011625641 | L50: =B50/D50 -> 1.1019621 | M50: =(B50/C50)*1000 -> 12.811016 | N50: =F50/B50 -> 10.311281 | O50: =E50/D50 -> 0.0011143096 | P50: =F50/E50 -> 10197.023 | Q50: =B50/E50 -> 988.91917 | R50: =B50/G50 -> 78.330231
A51: 万相台 | B51: =SUM(万相台!B72:B101) -> 10182.62 | C51: =SUM(万相台!C72:C101) -> 257113 | D51: =SUM(万相台!D72:D101) -> 10905 | E51: =SUM(万相台!E72:E101) -> 29 | F51: =SUM(万相台!F72:F101) -> 265570.08 | G51: =SUM(万相台!G72:G101) -> 231 | H51: =SUM(万相台!H72:H101) -> 56 | J51: =H51+I51 -> 56 | K51: =D51/C51 -> 0.042413258 | L51: =B51/D51 -> 0.93375699 | M51: =(B51/C51)*1000 -> 39.603676 | N51: =F51/B51 -> 26.080722 | O51: =E51/D51 -> 0.0026593306 | P51: =F51/E51 -> 9157.589 | Q51: =B51/E51 -> 351.12483 | R51: =B51/G51 -> 44.080606
...

Sheet 明星店铺
A1: Date 时间 | B1: Cost 花费 | C1: IMP 展示 | D1: Click 点击 | E1: Order 订单 | F1: Sales 销量 | G1: ShoppingCart 加入购物车 | H1: Bookmark-Product 宝贝收藏 | I1: Bookmark-Store 店铺收藏 | J1: CTR 点击率 | K1: CPC 点击成本 | L1: CPM 千次展现成本 | M1: ROI 投资回报率 | N1: CVR 点击转化率 | O1: ASP 订单均价 | P1: Cporder 订单成本 | Q1: CPshopping cart 加购成本 | R1: 加购率
A2: 44197 | B2: 56.54 | C2: 42 | D2: 18 | E2: 0 | F2: 0 | G2: 0 | H2: 0 | I2: 2 | J2: =D2/C2 -> 0.42857143 | K2: =B2/D2 -> 3.1411111 | L2: 1346.19 | M2: 0 | N2: 0 | O2: =F2/E2 -> #DIV/0! | P2: =B2/E2 -> #DIV/0! | Q2: =B2/G2 -> #DIV/0!
A3: 44198 | B3: 36.58 | C3: 26 | D3: 11 | E3: 0 | F3: 0 | G3: 0 | H3: 0 | I3: 2 | J3: =D3/C3 -> 0.42307692 | K3: =B3/D3 -> 3.3254545 | L3: 1406.92 | M3: 0 | N3: 0 | O3: =F3/E3 -> #DIV/0! | P3: =B3/E3 -> #DIV/0! | Q3: =B3/G3 -> #DIV/0!
A4: 44199 | B4: 49.47 | C4: 39 | D4: 11 | E4: 0 | F4: 0 | G4: 0 | H4: 0 | I4: 3 | J4: =D4/C4 -> 0.28205128 | K4: =B4/D4 -> 4.4972727 | L4: 1268.46 | M4: 0 | N4: 0 | O4: =F4/E4 -> #DIV/0! | P4: =B4/E4 -> #DIV/0! | Q4: =B4/G4 -> #DIV/0!
A5: 44200 | B5: 78.09 | C5: 62 | D5: 30 | E5: 0 | F5: 0 | G5: 1 | H5: 0 | I5: 0 | J5: =D5/C5 -> 0.48387097 | K5: =B5/D5 -> 2.603 | L5: 1259.52 | M5: 0 | N5: 0 | O5: =F5/E5 -> #DIV/0! | P5: =B5/E5 -> #DIV/0! | Q5: =B5/G5 -> 78.09
A6: 44201 | B6: 59.83 | C6: 50 | D6: 20 | E6: 0 | F6: 0 | G6: 1 | H6: 0 | I6: 2 | J6: =D6/C6 -> 0.4 | K6: =B6/D6 -> 2.9915 | L6: 1196.6 | M6: 0 | N6: 0 | O6: =F6/E6 -> #DIV/0! | P6: =B6/E6 -> #DIV/0! | Q6: =B6/G6 -> 59.83
A7: 44202 | B7: 78.24 | C7: 58 | D7: 31 | E7: 0 | F7: 0 | G7: 0 | H7: 0 | I7: 2 | J7: =D7/C7 -> 0.53448276 | K7: =B7/D7 -> 2.523871 | L7: 1348.97 | M7: 0 | N7: 0 | O7: =F7/E7 -> #DIV/0! | P7: =B7/E7 -> #DIV/0! | Q7: =B7/G7 -> #DIV/0!
A8: 44203 | B8: 72.5 | C8: 71 | D8: 23 | E8: 0 | F8: 0 | G8: 2 | H8: 0 | I8: 1 | J8: =D8/C8 -> 0.32394366 | K8: =B8/D8 -> 3.1521739 | L8: 1021.13 | M8: 0 | N8: 0 | O8: =F8/E8 -> #DIV/0! | P8: =B8/E8 -> #DIV/0! | Q8: =B8/G8 -> 36.25
A9: 44204 | B9: 72.51 | C9: 70 | D9: 22 | E9: 0 | F9: 0 | G9: 0 | H9: 0 | I9: 1 | J9: =D9/C9 -> 0.31428571 | K9: =B9/D9 -> 3.2959091 | L9: 1035.86 | M9: 0 | N9: 0 | O9: =F9/E9 -> #DIV/0! | P9: =B9/E9 -> #DIV/0! | Q9: =B9/G9 -> #DIV/0!
A10: 44205 | B10: 66.9 | C10: 81 | D10: 8 | E10: 0 | F10: 0 | G10: 0 | H10: 0 | I10: 0 | J10: =D10/C10 -> 0.098765432 | K10: =B10/D10 -> 8.3625 | L10: 825.93 | M10: 0 | N10: 0 | O10: =F10/E10 -> #DIV/0! | P10: =B10/E10 -> #DIV/0! | Q10: =B10/G10 -> #DIV/0!
A11: 44206 | B11: 41.51 | C11: 38 | D11: 9 | E11: 0 | F11: 0 | G11: 0 | H11: 0 | I11: 1 | J11: =D11/C11 -> 0.23684211 | K11: =B11/D11 -> 4.6122222 | L11: 1092.37 | M11: 0 | N11: 0 | O11: =F11/E11 -> #DIV/0! | P11: =B11/E11 -> #DIV/0! | Q11: =B11/G11 -> #DIV/0!
A12: 44207 | B12: 56.58 | C12: 51 | D12: 16 | E12: 0 | F12: 0 | G12: 2 | H12: 0 | I12: 0 | J12: =D12/C12 -> 0.31372549 | K12: =B12/D12 -> 3.53625 | L12: 1109.41 | M12: 0 | N12: 0 | O12: =F12/E12 -> #DIV/0! | P12: =B12/E12 -> #DIV/0! | Q12: =B12/G12 -> 28.29
A13: 44208 | B13: 56.94 | C13: 57 | D13: 13 | E13: 0 | F13: 0 | G13: 1 | H13: 1 | I13: 0 | J13: =D13/C13 -> 0.22807018 | K13: =B13/D13 -> 4.38 | L13: 998.95 | M13: 0 | N13: 0 | O13: =F13/E13 -> #DIV/0! | P13: =B13/E13 -> #DIV/0! | Q13: =B13/G13 -> 56.94
... A18: 44213 | B18: 49.73 | C18: 42 | D18: 11 | E18: 0 | F18: 0 | G18: 2 | H18: 2 | I18: 1 | J18: =D18/C18 -> 0.26190476 | K18: =B18/D18 -> 4.5209091 | L18: 1184.05 | M18: 0 | N18: 0 | O18: =F18/E18 -> #DIV/0! | P18: =B18/E18 -> #DIV/0! | Q18: =B18/G18 -> 24.865
A19: 44214 | B19: 50.64 | C19: 41 | D19: 18 | E19: 1 | F19: 0.01 | G19: 2 | H19: 0 | I19: 0 | J19: =D19/C19 -> 0.43902439 | K19: =B19/D19 -> 2.8133333 | L19: =B19/(C19/1000) -> 1235.122 | M19: 0 | N19: 0 | O19: =F19/E19 -> 0.01 | P19: =B19/E19 -> 50.64 | Q19: =B19/G19 -> 25.32
A20: 44215 | B20: 50.78 | C20: 39 | D20: 16 | E20: 0 | F20: 0 | G20: 0 | H20: 0 | I20: 1 | J20: =D20/C20 -> 0.41025641 | K20: =B20/D20 -> 3.17375 | L20: =B20/(C20/1000) -> 1302.0513 | M20: 0 | N20: 0 | O20: =F20/E20 -> #DIV/0! | P20: =B20/E20 -> #DIV/0! | Q20: =B20/G20 -> #DIV/0!
A21: 44216 | B21: 71.75 | C21: 58 | D21: 32 | E21: 1 | F21: 0.01 | G21: 0 | H21: 0 | I21: 2 | J21: =D21/C21 -> 0.55172414 | K21: =B21/D21 -> 2.2421875 | L21: =B21/(C21/1000) -> 1237.069 | M21: 0 | N21: 0 | O21: =F21/E21 -> 0.01 | P21: =B21/E21 -> 71.75 | Q21: =B21/G21 -> #DIV/0!
A22: 44217 | B22: 52.78 | C22: 38 | D22: 18 | E22: 1 | F22: 0.01 | G22: 0 | H22: 0 | I22: 0 | J22: =D22/C22 -> 0.47368421 | K22: =B22/D22 -> 2.9322222 | L22: =B22/(C22/1000) -> 1388.9474 | M22: 0 | N22: 0 | O22: =F22/E22 -> 0.01 | P22: =B22/E22 -> 52.78 | Q22: =B22/G22 -> #DIV/0!
A23: 44218 | B23: 49.79 | C23: 43 | D23: 14 | E23: 0 | F23: 0 | G23: 0 | H23: 0 | I23: 0 | J23: =D23/C23 -> 0.3255814 | K23: =B23/D23 -> 3.5564286 | L23: =B23/(C23/1000) -> 1157.907 | M23: 0 | N23: 0 | O23: =F23/E23 -> #DIV/0! | P23: =B23/E23 -> #DIV/0! | Q23: =B23/G23 -> #DIV/0!
A24: 44219 | B24: 60.91 | C24: 67 | D24: 13 | E24: 0 | F24: 0 | G24: 1 | H24: 0 | I24: 2 | J24: =D24/C24 -> 0.19402985 | K24: =B24/D24 -> 4.6853846 | L24: =B24/(C24/1000) -> 909.10448 | M24: 0 | N24: 0 | O24: =F24/E24 -> #DIV/0! | P24: =B24/E24 -> #DIV/0! | Q24: =B24/G24 -> 60.91
A25: 44220 | B25: 54.85 | C25: 50 | D25: 15 | E25: 0 | F25: 0 | G25: 1 | H25: 0 | I25: 1 | J25: =D25/C25 -> 0.3 | K25: =B25/D25 -> 3.6566667 | L25: =B25/(C25/1000) -> 1097 | M25: 0 | N25: 0 | O25: =F25/E25 -> #DIV/0! | P25: =B25/E25 -> #DIV/0! | Q25: =B25/G25 -> 54.85
A26: 44221 | B26: 35.77 | C26: 36 | D26: 10 | E26: 0 | F26: 0 | G26: 1 | H26: 0 | I26: 1 | J26: =D26/C26 -> 0.27777778 | K26: =B26/D26 -> 3.577 | L26: =B26/(C26/1000) -> 993.61111 | M26: 0 | N26: 0 | O26: =F26/E26 -> #DIV/0! | P26: =B26/E26 -> #DIV/0! | Q26: =B26/G26 -> 35.77
A27: 44222 | B27: 45.51 | C27: 40 | D27: 21 | E27: 0 | F27: 0 | G27: 0 | H27: 1 | I27: 1 | J27: =D27/C27 -> 0.525 | K27: =B27/D27 -> 2.1671429 | L27: =B27/(C27/1000) -> 1137.75 | M27: 0 | N27: 0 | O27: =F27/E27 -> #DIV/0! | P27: =B27/E27 -> #DIV/0! | Q27: =B27/G27 -> #DIV/0!
A28: 44223 | B28: 51.74 | C28: 39 | D28: 26 | E28: 0 | F28: 0 | G28: 1 | H28: 0 | I28: 0 | J28: =D28/C28 -> 0.66666667 | K28: =B28/D28 -> 1.99 | L28: =B28/(C28/1000) -> 1326.6667 | M28: 0 | N28: 0 | O28: =F28/E28 -> #DIV/0! | P28: =B28/E28 -> #DIV/0! | Q28: =B28/G28 -> 51.74
A29: 44224 | B29: 58.41 | C29: 41 | D29: 25 | E29: 0 | F29: 0 | G29: 2 | H29: 1 | I29: 2 | J29: =D29/C29 -> 0.6097561 | K29: =B29/D29 -> 2.3364 | L29: =B29/(C29/1000) -> 1424.6341 | M29: 0 | N29: 0 | O29: =F29/E29 -> #DIV/0! | P29: =B29/E29 -> #DIV/0! | Q29: =B29/G29 -> 29.205
A30: 44225 | B30: 41.08 | C30: 28 | D30: 10 | E30: 0 | F30: 0 | G30: 2 | H30: 0 | I30: 0 | J30: =D30/C30 -> 0.35714286 | K30: =B30/D30 -> 4.108 | L30: =B30/(C30/1000) -> 1467.1429 | M30: 0 | N30: 0 | O30: =F30/E30 -> #DIV/0! | P30: =B30/E30 -> #DIV/0! | Q30: =B30/G30 -> 20.54
... A32: 44227 | B32: 0 | C32: 0 | D32: 0 | E32: 0 | F32: 0 | G32: 0 | H32: 0 | I32: 0 | J32: =D32/C32 -> #DIV/0! | K32: =B32/D32 -> #DIV/0! | L32: =B32/(C32/1000) -> #DIV/0! | M32: 0 | N32: 0 | O32: =F32/E32 -> #DIV/0! | P32: =B32/E32 -> #DIV/0! | Q32: =B32/G32 -> #DIV/0!
A33: =A32+1 -> 44228 | B33: 0 | C33: 0 | D33: 0 | E33: 0 | F33: 0 | G33: 0 | H33: 0 | I33: 0 | J33: =D33/C33 -> #DIV/0! | K33: =B33/D33 -> #DIV/0! | L33: =B33/(C33/1000) -> #DIV/0! | M33: 0 | N33: 0 | O33: =F33/E33 -> #DIV/0! | P33: =B33/E33 -> #DIV/0! | Q33: =B33/G33 -> #DIV/0!
A34: =A33+1 -> 44229 | B34: 58.2 | C34: 54 | D34: 20 | E34: 0 | F34: 0 | G34: 1 | H34: 0 | I34: 1 | J34: =D34/C34 -> 0.37037037 | K34: =B34/D34 -> 2.91 | L34: =B34/(C34/1000) -> 1077.7778 | M34: 0 | N34: 0 | O34: =F34/E34 -> #DIV/0! | P34: =B34/E34 -> #DIV/0! | Q34: =B34/G34 -> 58.2
A35: =A34+1 -> 44230 | B35: 81.92 | C35: 71 | D35: 30 | E35: 0 | F35: 0 | G35: 4 | H35: 1 | I35: 1 | J35: =D35/C35 -> 0.42253521 | K35: =B35/D35 -> 2.7306667 | L35: =B35/(C35/1000) -> 1153.8028 | M35: 0 | N35: 0 | O35: =F35/E35 -> #DIV/0! | P35: =B35/E35 -> #DIV/0! | Q35: =B35/G35 -> 20.48
A36: =A35+1 -> 44231 | B36: 41.85 | C36: 35 | D36: 16 | E36: 0 | F36: 0 | G36: 1 | H36: 2 | I36: 0 | J36: =D36/C36 -> 0.45714286 | K36: =B36/D36 -> 2.615625 | L36: =B36/(C36/1000) -> 1195.7143 | M36: 0 | N36: 0 | O36: =F36/E36 -> #DIV/0! | P36: =B36/E36 -> #DIV/0! | Q36: =B36/G36 -> 41.85
A37: =A36+1 -> 44232 | B37: 72.21 | C37: 57 | D37: 11 | E37: 0 | F37: 0 | G37: 0 | H37: 0 | I37: 1 | J37: =D37/C37 -> 0.19298246 | K37: =B37/D37 -> 6.5645455 | L37: =B37/(C37/1000) -> 1266.8421 | M37: 0 | N37: 0 | O37: =F37/E37 -> #DIV/0! | P37: =B37/E37 -> #DIV/0! | Q37: =B37/G37 -> #DIV/0!
A38: =A37+1 -> 44233 | B38: 43.5 | C38: 52 | D38: 12 | E38: 0 | F38: 0 | G38: 0 | H38: 0 | I38: 0 | J38: =D38/C38 -> 0.23076923 | K38: =B38/D38 -> 3.625 | L38: =B38/(C38/1000) -> 836.53846 | M38: 0 | N38: 0 | O38: =F38/E38 -> #DIV/0! | P38: =B38/E38 -> #DIV/0! | Q38: =B38/G38 -> #DIV/0!
A39: =A38+1 -> 44234 | B39: 23.77 | C39: 25 | D39: 7 | E39: 0 | F39: 0 | G39: 0 | H39: 0 | I39: 1 | J39: =D39/C39 -> 0.28 | K39: =B39/D39 -> 3.3957143 | L39: =B39/(C39/1000) -> 950.8 | M39: 0 | N39: 0 | O39: =F39/E39 -> #DIV/0! | P39: =B39/E39 -> #DIV/0! | Q39: =B39/G39 -> #DIV/0!
A40: =A39+1 -> 44235 | B40: 33.8 | C40: 33 | D40: 11 | E40: 0 | F40: 0 | G40: 0 | H40: 0 | I40: 0 | J40: =D40/C40 -> 0.33333333 | K40: =B40/D40 -> 3.0727273 | L40: =B40/(C40/1000) -> 1024.2424 | M40: 0 | N40: 0 | O40: =F40/E40 -> #DIV/0! | P40: =B40/E40 -> #DIV/0! | Q40: =B40/G40 -> #DIV/0!
A41: =A40+1 -> 44236 | B41: 29.93 | C41: 35 | D41: 5 | E41: 0 | F41: 0 | G41: 0 | H41: 0 | I41: 0 | J41: =D41/C41 -> 0.14285714 | K41: =B41/D41 -> 5.986 | L41: =B41/(C41/1000) -> 855.14286 | M41: 0 | N41: 0 | O41: =F41/E41 -> #DIV/0! | P41: =B41/E41 -> #DIV/0! | Q41: =B41/G41 -> #DIV/0!
A42: =A41+1 -> 44237 | B42: 50.8 | C42: 71 | D42: 15 | E42: 0 | F42: 0 | G42: 3 | H42: 0 | I42: 0 | J42: =D42/C42 -> 0.21126761 | K42: =B42/D42 -> 3.3866667 | L42: =B42/(C42/1000) -> 715.49296 | M42: 0 | N42: 0 | O42: =F42/E42 -> #DIV/0! | P42: =B42/E42 -> #DIV/0! | Q42: =B42/G42 -> 16.933333
A43: =A42+1 -> 44238 | B43: 24.51 | C43: 35 | D43: 8 | E43: 0 | F43: 0 | G43: 1 | H43: 0 | I43: 0 | J43: =D43/C43 -> 0.22857143 | K43: =B43/D43 -> 3.06375 | L43: =B43/(C43/1000) -> 700.28571 | M43: 0 | N43: 0 | O43: =F43/E43 -> #DIV/0! | P43: =B43/E43 -> #DIV/0! | Q43: =B43/G43 -> 24.51
A44: =A43+1 -> 44239 | B44: 42.93 | C44: 46 | D44: 16 | E44: 0 | F44: 0 | G44: 1 | H44: 0 | I44: 0 | J44: =D44/C44 -> 0.34782609 | K44: =B44/D44 -> 2.683125 | L44: =B44/(C44/1000) -> 933.26087 | M44: 0 | N44: 0 | O44: =F44/E44 -> #DIV/0! | P44: =B44/E44 -> #DIV/0! | Q44: =B44/G44 -> 42.93
... A67: =A66+1 -> 44262 | B67: 152.95 | C67: 313 | D67: 18 | E67: 0 | F67: 0 | G67: 0 | H67: 1 | I67: 0 | J67: =D67/C67 -> 0.057507987 | K67: =B67/D67 -> 8.4972222 | L67: =B67/(C67/1000) -> 488.65815 | M67: 0 | N67: 0 | O67: =F67/E67 -> #DIV/0! | P67: =B67/E67 -> #DIV/0! | Q67: =B67/G67 -> #DIV/0!
...

Sheet 直通车
A1: Date 时间 | B1: Cost 花费 | C1: IMP 展示 | D1: Click 点击 | E1: Order 订单 | F1: Sales 销量GMV | G1: ShoppingCart 加入购物车 | H1: Bookmark-Product 宝贝收藏 | I1: Bookmark-Store 店铺收藏 | J1: CTR 点击率 | K1: CPC 点击成本 | L1: ROI 投资回报率 | M1: CVR 点击转化率 | N1: ASP 订单均价 | O1: Cporder 订单成本 | P1: CPshopping cart 加购成本 | Q1: 收藏加购成本 | R1: 收藏加购数 | S1: 收藏加购率
A2: 44197 | B2: 110.86 | C2: 5918 | D2: 80 | E2: 0 | F2: 0 | G2: 2 | H2: 0 | I2: 0 | J2: =D2/C2 -> 0.01351808 | K2: 1.39 | L2: =F2/B2 -> 0 | M2: 0 | N2: =F2/E2 -> #DIV/0! | O2: =B2/E2 -> #DIV/0! | P2: =B2/G2 -> 55.43
A3: 44198 | B3: 99.61 | C3: 6436 | D3: 77 | E3: 0 | F3: 0 | G3: 1 | H3: 3 | I3: 1 | J3: =D3/C3 -> 0.011963953 | K3: 1.29 | L3: 0 | M3: 0 | N3: =F3/E3 -> #DIV/0! | O3: =B3/E3 -> #DIV/0! | P3: =B3/G3 -> 99.61
A4: 44199 | B4: 130.39 | C4: 6733 | D4: 87 | E4: 0 | F4: 0 | G4: 1 | H4: 0 | I4: 2 | J4: =D4/C4 -> 0.012921432 | K4: 1.5 | L4: 0 | M4: 0 | N4: =F4/E4 -> #DIV/0! | O4: =B4/E4 -> #DIV/0! | P4: =B4/G4 -> 130.39
A5: 44200 | B5: 96.83 | C5: 6249 | D5: 72 | E5: 0 | F5: 0 | G5: 1 | H5: 0 | I5: 0 | J5: =D5/C5 -> 0.011521843 | K5: 1.34 | L5: 0 | M5: 0 | N5: =F5/E5 -> #DIV/0! | O5: =B5/E5 -> #DIV/0! | P5: =B5/G5 -> 96.83
A6: 44201 | B6: 123.41 | C6: 5251 | D6: 89 | E6: 0 | F6: 0 | G6: 1 | H6: 0 | I6: 0 | J6: =D6/C6 -> 0.016949153 | K6: 1.39 | L6: 0 | M6: 0 | N6: =F6/E6 -> #DIV/0! | O6: =B6/E6 -> #DIV/0! | P6: =B6/G6 -> 123.41
A7: 44202 | B7: 236.6 | C7: 3547 | D7: 132 | E7: 0 | F7: 0 | G7: 2 | H7: 1 | I7: 1 | J7: =D7/C7 -> 0.037214548 | K7: 1.79 | L7: 0 | M7: 0 | N7: =F7/E7 -> #DIV/0! | O7: =B7/E7 -> #DIV/0! | P7: =B7/G7 -> 118.3
A8: 44203 | B8: 300 | C8: 2606 | D8: 124 | E8: 0 | F8: 0 | G8: 1 | H8: 0 | I8: 0 | J8: =D8/C8 -> 0.047582502 | K8: 2.42 | L8: 0 | M8: 0 | N8: =F8/E8 -> #DIV/0! | O8: =B8/E8 -> #DIV/0! | P8: =B8/G8 -> 300
A9: 44204 | B9: 449.36 | C9: 6075 | D9: 195 | E9: 1 | F9: 200 | G9: 1 | H9: 0 | I9: 0 | J9: =D9/C9 -> 0.032098765 | K9: 2.3 | L9: 0.45 | M9: =E9/D9 -> 0.0051282051 | N9: =F9/E9 -> 200 | O9: =B9/E9 -> 449.36 | P9: =B9/G9 -> 449.36
A10: 44205 | B10: 415.34 | C10: 7328 | D10: 234 | E10: 0 | F10: 0 | G10: 5 | H10: 1 | I10: 0 | J10: =D10/C10 -> 0.031932314 | K10: 1.77 | L10: 0 | M10: =E10/D10 -> 0 | N10: =F10/E10 -> #DIV/0! | O10: =B10/E10 -> #DIV/0! | P10: =B10/G10 -> 83.068
A11: 44206 | B11: 450 | C11: 8236 | D11: 277 | E11: 0 | F11: 0 | G11: 2 | H11: 2 | I11: 0 | J11: =D11/C11 -> 0.033632831 | K11: 1.62 | L11: 0 | M11: =E11/D11 -> 0 | N11: =F11/E11 -> #DIV/0! | O11: =B11/E11 -> #DIV/0! | P11: =B11/G11 -> 225
A12: 44207 | B12: 436.22 | C12: 16851 | D12: 297 | E12: 0 | F12: 0 | G12: 5 | H12: 3 | I12: 1 | J12: =D12/C12 -> 0.017625067 | K12: 1.47 | L12: 0 | M12: =E12/D12 -> 0 | N12: =F12/E12 -> #DIV/0! | O12: =B12/E12 -> #DIV/0! | P12: =B12/G12 -> 87.244
A13: 44208 | B13: 333.5 | C13: 19534 | D13: 222 | E13: 0 | F13: 0 | G13: 2 | H13: 3 | I13: 1 | J13: =D13/C13 -> 0.0113648 | K13: 1.95 | L13: 0 | M13: =E13/D13 -> 0 | N13: =F13/E13 -> #DIV/0! | O13: =B13/E13 -> #DIV/0! | P13: =B13/G13 -> 166.75
A14: 44209 | B14: 150 | C14: 6603 | D14: 77 | E14: 0 | F14: 0 | G14: 1 | H14: 1 | I14: 0 | J14: =D14/C14 -> 0.011661366 | K14: 1.5 | L14: 0 | M14: =E14/D14 -> 0 | N14: =F14/E14 -> #DIV/0! | O14: =B14/E14 -> #DIV/0! | P14: =B14/G14 -> 150
A15: 44210 | B15: 150 | C15: 6592 | D15: 71 | E15: 0 | F15: 0 | G15: 1 | H15: 0 | I15: 1 | J15: =D15/C15 -> 0.010770631 | K15: 2.11 | L15: 0 | M15: =E15/D15 -> 0 | N15: =F15/E15 -> #DIV/0! | O15: =B15/E15 -> #DIV/0! | P15: =B15/G15 -> 150
A16: 44211 | B16: 300 | C16: 12239 | D16: 152 | E16: 0 | F16: 0 | G16: 1 | H16: 0 | I16: 0 | J16: =D16/C16 -> 0.012419315 | K16: 1.97 | L16: 0 | M16: 0 | N16: =F16/E16 -> #DIV/0! | O16: =B16/E16 -> #DIV/0! | P16: =B16/G16 -> 300
A17: 44212 | B17: 300 | C17: 8888 | D17: 159 | E17: 0 | F17: 0 | G17: 5 | H17: 0 | I17: 0 | J17: =D17/C17 -> 0.017889289 | K17: 1.89 | L17: 0 | M17: 0 | N17: =F17/E17 -> #DIV/0! | O17: =B17/E17 -> #DIV/0! | P17: =B17/G17 -> 60
A18: 44213 | B18: 300 | C18: 13642 | D18: 216 | E18: 0 | F18: 0 | G18: 3 | H18: 1 | I18: 0 | J18: =D18/C18 -> 0.015833456 | K18: 1.39 | L18: 0 | M18: 0 | N18: =F18/E18 -> #DIV/0! | O18: =B18/E18 -> #DIV/0! | P18: =B18/G18 -> 100
A19: 44214 | B19: 300 | C19: 15538 | D19: 203 | E19: 0 | F19: 0 | G19: 3 | H19: 0 | I19: 0 | J19: =D19/C19 -> 0.013064744 | K19: =B19/D19 -> 1.4778325 | L19: =F19/B19 -> 0 | M19: =E19/D19 -> 0 | N19: =F19/E19 -> #DIV/0! | O19: =B19/E19 -> #DIV/0! | P19: =B19/G19 -> 100
A20: 44215 | B20: 300 | C20: 16331 | D20: 141 | E20: 0 | F20: 0 | G20: 0 | H20: 2 | I20: 1 | J20: =D20/C20 -> 0.0086338865 | K20: =B20/D20 -> 2.1276596 | L20: =F20/B20 -> 0 | M20: =E20/D20 -> 0 | N20: =F20/E20 -> #DIV/0! | O20: =B20/E20 -> #DIV/0! | P20: =B20/G20 -> #DIV/0!
A21: 44216 | B21: 300 | C21: 16383 | D21: 155 | E21: 0 | F21: 0 | G21: 3 | H21: 1 | I21: 1 | J21: =D21/C21 -> 0.0094610267 | K21: =B21/D21 -> 1.9354839 | L21: =F21/B21 -> 0 | M21: =E21/D21 -> 0 | N21: =F21/E21 -> #DIV/0! | O21: =B21/E21 -> #DIV/0! | P21: =B21/G21 -> 100
A22: 44217 | B22: 296.95 | C22: 18441 | D22: 173 | E22: 0 | F22: 0 | G22: 0 | H22: 0 | I22: 0 | J22: =D22/C22 -> 0.00938127 | K22: =B22/D22 -> 1.716474 | L22: =F22/B22 -> 0 | M22: =E22/D22 -> 0 | N22: =F22/E22 -> #DIV/0! | O22: =B22/E22 -> #DIV/0! | P22: =B22/G22 -> #DIV/0!
A23: 44218 | B23: 257.3 | C23: 13320 | D23: 213 | E23: 0 | F23: 0 | G23: 4 | H23: 0 | I23: 0 | J23: =D23/C23 -> 0.015990991 | K23: =B23/D23 -> 1.2079812 | L23: =F23/B23 -> 0 | M23: =E23/D23 -> 0 | N23: =F23/E23 -> #DIV/0! | O23: =B23/E23 -> #DIV/0! | P23: =B23/G23 -> 64.325
A24: 44219 | B24: 271.28 | C24: 14263 | D24: 237 | E24: 0 | F24: 0 | G24: 3 | H24: 0 | I24: 0 | J24: =D24/C24 -> 0.01661642 | K24: =B24/D24 -> 1.1446414 | L24: =F24/B24 -> 0 | M24: =E24/D24 -> 0 | N24: =F24/E24 -> #DIV/0! | O24: =B24/E24 -> #DIV/0! | P24: =B24/G24 -> 90.426667
A25: 44220 | B25: 200.22 | C25: 8266 | D25: 167 | E25: 0 | F25: 0 | G25: 2 | H25: 0 | I25: 0 | J25: =D25/C25 -> 0.020203242 | K25: =B25/D25 -> 1.1989222 | L25: =F25/B25 -> 0 | M25: =E25/D25 -> 0 | N25: =F25/E25 -> #DIV/0! | O25: =B25/E25 -> #DIV/0! | P25: =B25/G25 -> 100.11
A26: 44221 | B26: 0 | C26: 2 | D26: 0 | E26: 0 | F26: 0 | G26: 0 | H26: 0 | I26: 0 | J26: =D26/C26 -> 0 | K26: 0 | L26: =F26/B26 -> #DIV/0! | M26: =E26/D26 -> #DIV/0! | N26: =F26/E26 -> #DIV/0! | O26: =B26/E26 -> #DIV/0! | P26: =B26/G26 -> #DIV/0!
A27: 44222 | B27: 0 | C27: 0 | D27: 0 | E27: 0 | F27: 0 | G27: 0 | H27: 0 | I27: 0 | J27: =D27/C27 -> #DIV/0! | K27: 0 | L27: =F27/B27 -> #DIV/0! | M27: =E27/D27 -> #DIV/0! | N27: =F27/E27 -> #DIV/0! | O27: =B27/E27 -> #DIV/0! | P27: =B27/G27 -> #DIV/0!
A28: 44223 | B28: 0 | C28: 0 | D28: 0 | E28: 0 | F28: 0 | G28: 0 | H28: 0 | I28: 0 | J28: =D28/C28 -> #DIV/0! | K28: 0 | L28: =F28/B28 -> #DIV/0! | M28: =E28/D28 -> #DIV/0! | N28: =F28/E28 -> #DIV/0! | O28: =B28/E28 -> #DIV/0! | P28: =B28/G28 -> #DIV/0!
A29: 44224 | B29: 276.73 | C29: 16117 | D29: 177 | E29: 0 | F29: 0 | G29: 0 | H29: 0 | I29: 0 | J29: =D29/C29 -> 0.010982193 | K29: =B29/D29 -> 1.5634463 | L29: =F29/B29 -> 0 | M29: =E29/D29 -> 0 | N29: =F29/E29 -> #DIV/0! | O29: =B29/E29 -> #DIV/0! | P29: =B29/G29 -> #DIV/0!
A30: 44225 | B30: 300 | C30: 15678 | D30: 129 | E30: 0 | F30: 0 | G30: 2 | H30: 0 | I30: 1 | J30: =D30/C30 -> 0.0082280903 | K30: =B30/D30 -> 2.3255814 | L30: =F30/B30 -> 0 | M30: =E30/D30 -> 0 | N30: =F30/E30 -> #DIV/0! | O30: =B30/E30 -> #DIV/0! | P30: =B30/G30 -> 150
A31: 44226 | B31: 94.91 | C31: 6764 | D31: 69 | E31: 0 | F31: 0 | G31: 0 | H31: 0 | I31: 0 | J31: =D31/C31 -> 0.010201064 | K31: =B31/D31 -> 1.3755072 | L31: =F31/B31 -> 0 | M31: =E31/D31 -> 0 | N31: =F31/E31 -> #DIV/0! | O31: =B31/E31 -> #DIV/0! | P31: =B31/G31 -> #DIV/0!
A32: 44227 | B32: 0 | C32: 0 | D32: 0 | E32: 0 | F32: 0 | G32: 0 | H32: 0 | I32: 0 | J32: =D32/C32 -> #DIV/0! | K32: 0 | L32: =F32/B32 -> #DIV/0! | M32: =E32/D32 -> #DIV/0! | N32: =F32/E32 -> #DIV/0! | O32: =B32/E32 -> #DIV/0! | P32: =B32/G32 -> #DIV/0!
A33: =A32+1 -> 44228 | B33: 188.02 | C33: 7543 | D33: 131 | E33: 0 | F33: 0 | G33: 2 | H33: 0 | I33: 0 | J33: =D33/C33 -> 0.017367095 | K33: =B33/D33 -> 1.4352672 | L33: =F33/B33 -> 0 | M33: =E33/D33 -> 0 | N33: =F33/E33 -> #DIV/0! | O33: =B33/E33 -> #DIV/0! | P33: =B33/G33 -> 94.01
A34: =A33+1 -> 44229 | B34: 300 | C34: 12623 | D34: 188 | E34: 0 | F34: 0 | G34: 3 | H34: 4 | I34: 1 | J34: =D34/C34 -> 0.014893448 | K34: =B34/D34 -> 1.5957447 | L34: =F34/B34 -> 0 | M34: =E34/D34 -> 0 | N34: =F34/E34 -> #DIV/0! | O34: =B34/E34 -> #DIV/0! | P34: =B34/G34 -> 100
A35: =A34+1 -> 44230 | B35: 300 | C35: 12677 | D35: 175 | E35: 0 | F35: 0 | G35: 1 | H35: 1 | I35: 1 | J35: =D35/C35 -> 0.013804528 | K35: =B35/D35 -> 1.7142857 | L35: =F35/B35 -> 0 | M35: =E35/D35 -> 0 | N35: =F35/E35 -> #DIV/0! | O35: =B35/E35 -> #DIV/0! | P35: =B35/G35 -> 300
A36: =A35+1 -> 44231 | B36: 300 | C36: 15785 | D36: 162 | E36: 0 | F36: 0 | G36: 2 | H36: 4 | I36: 1 | J36: =D36/C36 -> 0.010262908 | K36: =B36/D36 -> 1.8518519 | L36: =F36/B36 -> 0 | M36: =E36/D36 -> 0 | N36: =F36/E36 -> #DIV/0! | O36: =B36/E36 -> #DIV/0! | P36: =B36/G36 -> 150
A37: =A36+1 -> 44232 | B37: 300 | C37: 15287 | D37: 152 | E37: 1 | F37: 6000 | G37: 3 | H37: 2 | I37: 0 | J37: =D37/C37 -> 0.0099430889 | K37: =B37/D37 -> 1.9736842 | L37: =F37/B37 -> 20 | M37: =E37/D37 -> 0.0065789474 | N37: =F37/E37 -> 6000 | O37: =B37/E37 -> 300 | P37: =B37/G37 -> 100
A38: =A37+1 -> 44233 | B38: 291.1 | C38: 16307 | D38: 148 | E38: 0 | F38: 0 | G38: 1 | H38: 0 | I38: 0 | J38: =D38/C38 -> 0.009075857 | K38: =B38/D38 -> 1.9668919 | L38: =F38/B38 -> 0 | M38: =E38/D38 -> 0 | N38: =F38/E38 -> #DIV/0! | O38: =B38/E38 -> #DIV/0! | P38: =B38/G38 -> 291.1
A39: =A38+1 -> 44234 | B39: 295.57 | C39: 15673 | D39: 129 | E39: 0 | F39: 0 | G39: 4 | H39: 4 | I39: 0 | J39: =D39/C39 -> 0.0082307152 | K39: =B39/D39 -> 2.2912403 | L39: =F39/B39 -> 0 | M39: =E39/D39 -> 0 | N39: =F39/E39 -> #DIV/0! | O39: =B39/E39 -> #DIV/0! | P39: =B39/G39 -> 73.8925
A40: =A39+1 -> 44235 | B40: 293.48 | C40: 23805 | D40: 149 | E40: 0 | F40: 0 | G40: 2 | H40: 1 | I40: 0 | J40: =D40/C40 -> 0.0062591892 | K40: =B40/D40 -> 1.9696644 | L40: =F40/B40 -> 0 | M40: =E40/D40 -> 0 | N40: =F40/E40 -> #DIV/0! | O40: =B40/E40 -> #DIV/0! | P40: =B40/G40 -> 146.74
...

Sheet 对比超品日
A2: 1月 | B2: Cost 花费 | D2: IMP 展示 | E2: Click 点击 | F2: Order 订单 | G2: Sales 销量 | H2: ShoppingCart 加入购物车 | I2: Bookmark-Product 宝贝收藏 | J2: Bookmark-Store 店铺收藏 | L2: CTR 点击率 | M2: CPC 点击成本 | O2: CPM 千次展现成本 | P2: ROI 投资回报率 | R2: CVR 点击转化率 | T2: ASP 订单均价 | U2: Cporder 订单成本 | V2: CPshopping cart 加购成本
A3: 钻展 | B3: 6.05 | D3: 1427 | E3: 1 | F3: - | G3: - | H3: - | I3: - | J3: - | L3: - | M3: - | O3: - | P3: - | R3: - | T3: - | U3: - | V3: -
A4: 明星店铺 | B4: 2731.45 | D4: 7691 | E4: 349 | F4: 0 | G4: 0 | H4: 2 | I4: 2 | J4: 11 | L4: =E4/D4 -> 0.045377714 | M4: =B4/E4 -> 7.8265043 | O4: =(B4/D4)*1000 -> 355.14888 | P4: =G4/B4 -> 0 | R4: =F4/E4 -> 0 | T4: =G4/F4 -> #DIV/0! | U4: =B4/F4 -> #DIV/0! | V4: =B4/H4 -> 1365.725
A5: 直通车 | B5: 1952.96 | D5: 39544 | E5: 1253 | F5: 2 | G5: 198 | H5: 46 | I5: 4 | J5: 8 | L5: =E5/D5 -> 0.031686223 | M5: =B5/E5 -> 1.5586273 | O5: =(B5/D5)*1000 -> 49.387012 | P5: =G5/B5 -> 0.10138456 | R5: =F5/E5 -> 0.0015961692 | T5: =G5/F5 -> 99 | U5: =B5/F5 -> 976.48 | V5: =B5/H5 -> 42.455652
A6: 引力魔方 | B6: - | D6: - | E6: - | F6: - | G6: - | H6: - | I6: - | J6: - | L6: - | M6: - | O6: - | P6: - | R6: - | T6: - | U6: - | V6: -
A7: 总计 | B7: =SUM(B3:B6) -> 4690.46 | D7: =SUM(D3:D6) -> 48662 | E7: =SUM(E3:E6) -> 1603 | F7: =SUM(F3:F6) -> 2 | G7: =SUM(G3:G6) -> 198 | H7: =SUM(H3:H6) -> 48 | I7: =SUM(I3:I6) -> 6 | J7: =SUM(J3:J6) -> 19 | L7: =E7/D7 -> 0.032941515 | M7: =B7/E7 -> 2.9260512 | O7: =(B7/D7)*1000 -> 96.388558 | P7: =G7/B7 -> 0.042213344 | R7: =F7/E7 -> 0.0012476606 | T7: =G7/F7 -> 99 | U7: =B7/F7 -> 2345.23 | V7: =B7/H7 -> 97.717917
A10: 2月 | B10: Cost 花费 | D10: IMP 展示 | E10: Click 点击 | F10: Order 订单 | G10: Sales 销量 | H10: ShoppingCart 加入购物车 | I10: Bookmark-Product 宝贝收藏 | J10: Bookmark-Store 店铺收藏 | L10: CTR 点击率 | M10: CPC 点击成本 | O10: CPM 千次展现成本 | P10: ROI 投资回报率 | R10: CVR 点击转化率 | T10: ASP 订单均价 | U10: Cporder 订单成本 | V10: CPshopping cart 加购成本
A11: 明星店铺 | B11: 22646 | D11: 24719 | E11: 1047 | F11: 1 | G11: 99 | H11: 13 | I11: 3 | J11: 20 | L11: =E11/D11 -> 0.042356082 | M11: =B11/E11 -> 21.629417 | O11: =(B11/D11)*1000 -> 916.13738 | P11: =G11/B11 -> 0.004371633 | R11: =F11/E11 -> 0.00095510984 | T11: =G11/F11 -> 99 | U11: =B11/F11 -> 22646 | V11: =B11/H11 -> 1742
A12: 直通车 | B12: 5688.53 | D12: 84202 | E12: 2773 | F12: 2 | G12: 198 | H12: 51 | I12: 14 | J12: 14 | L12: =E12/D12 -> 0.032932709 | M12: =B12/E12 -> 2.0513992 | O12: =(B12/D12)*1000 -> 67.558134 | P12: =G12/B12 -> 0.034806883 | R12: =F12/E12 -> 0.00072124053 | T12: =G12/F12 -> 99 | U12: =B12/F12 -> 2844.265 | V12: =B12/H12 -> 111.5398
A13: 引力魔方 | B13: 1337.93 | D13: 197627 | E13: 1649 | F13: 0 | G13: 0 | H13: 8 | I13: 12 | J13: 2 | L13: =E13/D13 -> 0.0083440016 | M13: =B13/E13 -> 0.8113584 | O13: =(B13/D13)*1000 -> 6.7699758 | P13: =G13/B13 -> 0 | R13: =F13/E13 -> 0 | T13: =G13/F13 -> #DIV/0! | U13: =B13/F13 -> #DIV/0! | V13: =B13/H13 -> 167.24125
A14: 总计 | B14: =SUM(B11:B13) -> 29672.46 | D14: =SUM(D11:D13) -> 306548 | E14: =SUM(E11:E13) -> 5469 | F14: =SUM(F11:F13) -> 3 | G14: =SUM(G11:G13) -> 297 | H14: =SUM(H11:H13) -> 72 | I14: =SUM(I11:I13) -> 29 | J14: =SUM(J11:J13) -> 36 | L14: =E14/D14 -> 0.017840599 | M14: =B14/E14 -> 5.4255732 | O14: =(B14/D14)*1000 -> 96.795477 | P14: =G14/B14 -> 0.010009281 | R14: =F14/E14 -> 0.00054854635 | T14: =G14/F14 -> 99 | U14: =B14/F14 -> 9890.82 | V14: =B14/H14 -> 412.1175
A17: 3月 | B17: Cost 花费 | D17: IMP 展示 | E17: Click 点击 | F17: Order 订单 | G17: Sales 销量 | H17: ShoppingCart 加入购物车 | I17: Bookmark-Product 宝贝收藏 | J17: Bookmark-Store 店铺收藏 | L17: CTR 点击率 | M17: CPC 点击成本 | O17: CPM 千次展现成本 | P17: ROI 投资回报率 | R17: CVR 点击转化率 | T17: ASP 订单均价 | U17: Cporder 订单成本 | V17: CPshopping cart 加购成本
A18: 明星店铺 | B18: 2866.29 | D18: 12670 | E18: 404 | F18: 3 | G18: 600 | H18: 2 | I18: 1 | J18: 12 | L18: =E18/D18 -> 0.031886346 | M18: =B18/E18 -> 7.0947772 | O18: =(B18/D18)*1000 -> 226.22652 | P18: =G18/B18 -> 0.20932983 | R18: =F18/E18 -> 0.0074257426 | T18: =G18/F18 -> 200 | U18: =B18/F18 -> 955.43 | V18: =B18/H18 -> 1433.145
A19: 直通车 | B19: 3311.5 | D19: 120004 | E19: 2346 | F19: 0 | G19: 0 | H19: 1 | I19: 2 | J19: 8 | L19: =E19/D19 -> 0.019549348 | M19: =B19/E19 -> 1.4115516 | O19: =(B19/D19)*1000 -> 27.594914 | P19: =G19/B19 -> 0 | R19: =F19/E19 -> 0 | T19: =G19/F19 -> #DIV/0! | U19: =B19/F19 -> #DIV/0! | V19: =B19/H19 -> 3311.5
A20: 引力魔方 | B20: 2031.5 | D20: 219571 | E20: 1511 | F20: 0 | G20: 0 | H20: 2 | I20: 14 | J20: 0 | L20: =E20/D20 -> 0.0068816009 | M20: =B20/E20 -> 1.3444739 | O20: =(B20/D20)*1000 -> 9.2521326 | P20: =G20/B20 -> 0 | R20: =F20/E20 -> 0 | T20: =G20/F20 -> #DIV/0! | U20: =B20/F20 -> #DIV/0! | V20: =B20/H20 -> 1015.75
A21: 总计 | B21: =SUM(B18:B20) -> 8209.29 | D21: =SUM(D18:D20) -> 352245 | E21: =SUM(E18:E20) -> 4261 | F21: =SUM(F18:F20) -> 3 | G21: =SUM(G18:G20) -> 600 | H21: =SUM(H18:H20) -> 5 | I21: =SUM(I18:I20) -> 17 | J21: =SUM(J18:J20) -> 20 | L21: =E21/D21 -> 0.012096694 | M21: =B21/E21 -> 1.9266111 | O21: =(B21/D21)*1000 -> 23.305625 | P21: =G21/B21 -> 0.073087928 | R21: =F21/E21 -> 0.00070406008 | T21: =G21/F21 -> 200 | U21: =B21/F21 -> 2736.43 | V21: =B21/H21 -> 1641.858
A25: 2023年
A26: 8月 | B26: Cost 花费 | D26: IMP 展示 | E26: Click 点击 | F26: Order 订单 | G26: Sales 销量 | H26: ShoppingCart 加入购物车 | I26: Bookmark-Product 宝贝收藏 | J26: Bookmark-Store 店铺收藏 | L26: CTR 点击率 | M26: CPC 点击成本 | O26: CPM 千次展现成本 | P26: ROI 投资回报率 | R26: CVR 点击转化率 | T26: ASP 订单均价 | U26: Cporder 订单成本 | V26: CPshopping cart 加购成本
A27: 明星店铺 | B27: =SUM(明星店铺!B514:B522) -> 496.42 | D27: =SUM(明星店铺!C514:C522) -> 670 | E27: =SUM(明星店铺!D514:D522) -> 180 | F27: =SUM(明星店铺!E514:E522) -> 3 | G27: =SUM(明星店铺!F514:F522) -> 3 | H27: =SUM(明星店铺!G514:G522) -> 38 | I27: =SUM(明星店铺!H514:H522) -> 8 | J27: =SUM(明星店铺!I514:I522) -> 6 | L27: =E27/D27 -> 0.26865672 | M27: =B27/E27 -> 2.7578889 | O27: =(B27/D27)*1000 -> 740.92537 | P27: =G27/B27 -> 0.0060432698 | R27: =F27/E27 -> 0.016666667 | T27: =G27/F27 -> 1 | U27: =B27/F27 -> 165.47333 | V27: =B27/H27 -> 13.063684
